Workbook

Sheet Assessment_Instructions
A1: MS EXCEL ASSESSMENT
A3: CANDIDATE INFORMATION
A4: Candidate Name: | B4: Nikhil Goswami
A5: Date: | B5: 46207
A6: Position:
A7: Time Allowed: | B7: 90 Minutes
A9: GENERAL INSTRUCTIONS
A10: 1. This workbook contains 5 data sheets: Fleet_Vehicle_Data, Trip_Data, Driver_Data, Maintenance_Data, and Revenue_Summary_Raw.
A11: 2. Create your answers in NEW sheets within this workbook. Name them as specified in each task.
A12: 3. Use proper formatting, number formats (₹ for currency), and conditional formatting where appropriate.
A13: 4. Show all formulas - do NOT paste values only unless specifically asked.
A14: 5. Charts should have proper titles, axis labels, legends, and data labels.
A15: 6. Save your work frequently. Submit the completed workbook.
A16: 7. Partial marks will be awarded for partially correct answers.
A17: 8. You may use any Excel functions including VLOOKUP, INDEX-MATCH, SUMIFS, Pivot Tables, etc.

Sheet Assessment_Tasks
A2: ASSESSMENT TASKS
A4: SECTION A: DATA ANALYSIS & FORMULAS
A5: Task A1 | B5: Create a new sheet 'Analysis_A1'. Build a summary table showing: - Total vehicles per City - Average Mileage per Fuel Type - Total Monthly Revenue by Service Type - Count of vehicles with Rating > 4.0 per City
A6: Task A2 | B6: In the same sheet, create a section that uses VLOOKUP/INDEX-MATCH to: - Allow user to enter a Vehicle_ID and auto-populate: Make, Model, City, Status, Monthly Revenue - Create a dropdown validation for Vehicle_ID selection
A7: Task A3 | B7: Using Trip_Data, calculate for each city: - Average fare per km - Cancellation rate (%) - Average customer rating - Total revenue from surge trips (Surge > 1.0)
A8: SECTION B: DATA CLEANING & VALIDATION
A9: Task B1 | B9: In 'Revenue_Summary_Raw', the Profit column has errors. Create a new sheet 'Cleaned_Revenue' where: - Recalculate Profit = Revenue - Fuel_Cost - Maintenance_Cost - Driver_Cost - Add a column 'Profit_Margin_%' = (Profit/Revenue)*100 - Add a column 'Error_Flag' that shows 'ERROR' if original Profit ≠ Recalculated Profit (tolerance ±1) - Highlight all error rows in RED
A10: Task B2 | B10: Create a new sheet 'Validation_Report' containing: - List of vehicles with Odometer > 80,000 km (flag for replacement review) - Drivers with Violations > 5 AND Rating < 4.0 (flag for review) - Vehicles with 'Electric' fuel type but non-zero mileage_kmpl (data error) - Trips where Duration < Distance/60 (impossible speed > 60 km/min) Format as a professional report with color-coded severity.
A11: SECTION C: PIVOT TABLES & CHARTS
A12: Task C1 | B12: Create a new sheet 'Pivot_Analysis'. Build the following Pivot Tables: PT1: Revenue by City and Month (with Grand Totals) PT2: Average Rating by Service Type and City PT3: Maintenance Cost by Vehicle Make and Maintenance Type Apply proper formatting and Pivot Table styles.
A13: Task C2 | B13: Create a new sheet 'Dashboard_Charts'. Build these charts: Chart 1: Clustered Bar - Revenue comparison across cities by service type Chart 2: Pie Chart - Fleet composition by fuel type Chart 3: Line Chart - Monthly revenue trend by city Chart 4: Combo Chart - Trips vs Revenue by city (dual axis) All charts must have titles, labels, legends, and professional formatting.
A14: SECTION D: ADVANCED ANALYSIS
A15: Task D1 | B15: Create a sheet 'Fleet_Efficiency'. Calculate: - Revenue per km for each vehicle (using Trip_Data) - Cost efficiency = (Maintenance_Cost / Revenue) × 100 for each vehicle - Driver utilization = (Active_Trips / Total_Possible_Trips) assuming 8 trips/day - Rank vehicles using the RANK function - Apply conditional formatting: Green (top 25%), Yellow (middle 50%), Red (bottom 25%)
A16: Task D2 | B16: Create a sheet 'Scenario_Analysis': - Build a what-if model: If fuel prices increase by 10%, 20%, 30% - calculate impact on profit - Use Data Tables (one-variable) to show profit at different surge multiplier levels (1.0 to 2.5) - Calculate break-even trip count per vehicle per month - Use Goal Seek or Solver setup (describe approach if Solver unavailable)
A17: SECTION E: FORMATTING & PRESENTATION
A18: Task E1 | B18: Create an 'Executive_Summary' sheet: - Professional header with company logo placeholder - KPI cards showing: Total Fleet Size, Active Vehicles, Total Revenue, Avg Rating - Month-over-month growth indicators with UP/DOWN arrows (▲/▼) - Top 5 and Bottom 5 performing vehicles - Use shapes, borders, colors, and conditional formatting creatively

Sheet Fleet_Vehicle_Data
A1: Vehicle_ID | B1: Make | C1: Model | D1: Year | E1: Body_Type | F1: Fuel_Type | G1: Odometer_km | H1: Status | I1: City | J1: Service_Type | K1: Mileage_kmpl | L1: Last_Service_Date | M1: Monthly_Revenue_INR | N1: Insurance_Premium_INR | O1: Driver_Rating
A2: VH001 | B2: Toyota | C2: Camry | D2: 2021 | E2: Sedan | F2: Petrol | G2: 45000 | H2: Active | I2: Mumbai | J2: Corporate | K2: 15.5 | L2: 2024-01-15 | M2: 12500 | N2: 850 | O2: 4.2
A3: VH002 | B3: Hyundai | C3: Creta | D3: 2022 | E3: SUV | F3: Diesel | G3: 32000 | H3: Active | I3: Delhi | J3: Corporate | K3: 14.2 | L3: 2024-02-20 | M3: 9800 | N3: 920 | O3: 4.5
A4: VH003 | B4: Maruti | C4: Swift Dzire | D4: 2020 | E4: Sedan | F4: CNG | G4: 68000 | H4: Active | I4: Bangalore | J4: Ride-Hailing | K4: 22.1 | L4: 2023-11-10 | M4: 15200 | N4: 680 | O4: 3.8
A5: VH004 | B5: Tata | C5: Nexon EV | D5: 2023 | E5: SUV | F5: Electric | G5: 15000 | H5: Active | I5: Hyderabad | J5: Last-Mile | K5: 0 | L5: 2024-03-05 | M5: 7500 | N5: 1100 | O5: 4.7
A6: VH005 | B6: Mahindra | C6: XUV700 | D6: 2022 | E6: SUV | F6: Diesel | G6: 41000 | H6: Under Maintenance | I6: Pune | J6: Corporate | K6: 13.8 | L6: 2024-01-28 | M6: 11200 | N6: 1050 | O6: 4.1
A7: VH006 | B7: Honda | C7: City | D7: 2021 | E7: Sedan | F7: Petrol | G7: 52000 | H7: Active | I7: Chennai | J7: Ride-Hailing | K7: 16.3 | L7: 2023-12-15 | M7: 13800 | N7: 780 | O7: 3.9
A8: VH007 | B8: Kia | C8: Seltos | D8: 2023 | E8: SUV | F8: Petrol | G8: 18000 | H8: Active | I8: Mumbai | J8: Corporate | K8: 14.8 | L8: 2024-04-01 | M8: 6200 | N8: 980 | O8: 4.6
A9: VH008 | B9: MG | C9: ZS EV | D9: 2022 | E9: SUV | F9: Electric | G9: 28000 | H9: Active | I9: Delhi | J9: Last-Mile | K9: 0 | L9: 2024-02-10 | M9: 8900 | N9: 1200 | O9: 4.3
A10: VH009 | B10: Maruti | C10: Ertiga | D10: 2020 | E10: MPV | F10: CNG | G10: 75000 | H10: Active | I10: Bangalore | J10: Shuttle | K10: 19.5 | L10: 2023-10-20 | M10: 16800 | N10: 720 | O10: 3.7
A11: VH010 | B11: Toyota | C11: Innova Crysta | D11: 2021 | E11: MPV | F11: Diesel | G11: 58000 | H11: Active | I11: Hyderabad | J11: Shuttle | K11: 12.1 | L11: 2023-09-15 | M11: 14500 | N11: 1350 | O11: 4.4
A12: VH011 | B12: Hyundai | C12: Aura | D12: 2022 | E12: Sedan | F12: CNG | G12: 35000 | H12: Active | I12: Pune | J12: Ride-Hailing | K12: 24.5 | L12: 2024-01-05 | M12: 10200 | N12: 620 | O12: 4
A13: VH012 | B13: Tata | C13: Tigor EV | D13: 2023 | E13: Sedan | F13: Electric | G13: 12000 | H13: Active | I13: Chennai | J13: Last-Mile | K13: 0 | L13: 2024-03-20 | M13: 5800 | N13: 950 | O13: 4.8
... A31: VH030 | B31: Toyota | C31: Glanza | D31: 2023 | E31: Hatchback | F31: Petrol | G31: 10000 | H31: Active | I31: Chennai | J31: Last-Mile | K31: 21.5 | L31: 2024-04-15 | M31: 4200 | N31: 700 | O31: 4.8

Sheet Trip_Data
A1: Trip_ID | B1: Vehicle_ID | C1: Driver_ID | D1: Trip_Date | E1: City | F1: Service_Type | G1: Distance_km | H1: Duration_min | I1: Base_Fare_INR | J1: Surge_Multiplier | K1: Total_Fare_INR | L1: Payment_Mode | M1: Customer_Rating | N1: Wait_Time_min | O1: Cancelled | P1: Validation
A2: TR0001 | B2: VH021 | C2: DR008 | D2: 2024-01-24 | E2: Bangalore | F2: Ride-Hailing | G2: 16.1 | H2: 79 | I2: 322.44 | J2: 1 | K2: 322.44 | L2: Corporate Account | M2: 2.6 | N2: 3.2 | O2: No | P2: =IF(H2<(G2/60),"Impossible Speed","OK") -> OK
A3: TR0002 | B3: VH008 | C3: DR033 | D3: 2024-01-18 | E3: Delhi | F3: Shuttle | G3: 15.9 | H3: 76 | I3: 178.23 | J3: 2 | K3: 356.46 | L3: UPI | M3: 3.4 | N3: 4.7 | O3: No | P3: =IF(H3<(G3/60),"Impossible Speed","OK") -> OK
A4: TR0003 | B4: VH025 | C4: DR022 | D4: 2024-01-03 | E4: Hyderabad | F4: Corporate | G4: 24.6 | H4: 87 | I4: 257.49 | J4: 1.2 | K4: 308.99 | L4: Corporate Account | M4: 4.9 | N4: 10.1 | O4: No | P4: =IF(H4<(G4/60),"Impossible Speed","OK") -> OK
A5: TR0004 | B5: VH018 | C5: DR019 | D5: 2024-03-19 | E5: Delhi | F5: Corporate | G5: 4.9 | H5: 24 | I5: 93.11 | J5: 1 | K5: 93.11 | L5: Cash | M5: 3.2 | N5: 16.3 | O5: No | P5: =IF(H5<(G5/60),"Impossible Speed","OK") -> OK
A6: TR0005 | B6: VH012 | C6: DR011 | D6: 2024-03-12 | E6: Delhi | F6: Last-Mile | G6: 46.2 | H6: 185 | I6: 712.96 | J6: 1.5 | K6: 1069.44 | L6: UPI | M6: 3.7 | N6: 7.5 | O6: No | P6: =IF(H6<(G6/60),"Impossible Speed","OK") -> OK
A7: TR0006 | B7: VH030 | C7: DR041 | D7: 2024-02-22 | E7: Bangalore | F7: Corporate | G7: 16.4 | H7: 52 | I7: 225.11 | J7: 1 | K7: 225.11 | L7: Corporate Account | M7: 3 | N7: 13 | O7: No | P7: =IF(H7<(G7/60),"Impossible Speed","OK") -> OK
A8: TR0007 | B8: VH029 | C8: DR042 | D8: 2024-04-05 | E8: Bangalore | F8: Ride-Hailing | G8: 17.5 | H8: 72 | I8: 292.3 | J8: 1.5 | K8: 438.45 | L8: Wallet | M8: 3 | N8: 24.9 | O8: No | P8: =IF(H8<(G8/60),"Impossible Speed","OK") -> OK
A9: TR0008 | B9: VH017 | C9: DR032 | D9: 2024-01-25 | E9: Mumbai | F9: Corporate | G9: 11.6 | H9: 48 | I9: 211.98 | J9: 1.2 | K9: 254.38 | L9: Wallet | N9: 24.9 | O9: Yes | P9: =IF(H9<(G9/60),"Impossible Speed","OK") -> OK
A10: TR0009 | B10: VH017 | C10: DR017 | D10: 2024-01-22 | E10: Chennai | F10: Corporate | G10: 44.9 | H10: 169 | I10: 696.99 | J10: 1 | K10: 696.99 | L10: Card | M10: 2.9 | N10: 1.1 | O10: No | P10: =IF(H10<(G10/60),"Impossible Speed","OK") -> OK
A11: TR0010 | B11: VH024 | C11: DR047 | D11: 2024-03-17 | E11: Delhi | F11: Corporate | G11: 56.8 | H11: 190 | I11: 850.3 | J11: 1 | K11: 850.3 | L11: Card | M11: 3.8 | N11: 19.7 | O11: No | P11: =IF(H11<(G11/60),"Impossible Speed","OK") -> OK
A12: TR0011 | B12: VH017 | C12: DR001 | D12: 2024-03-16 | E12: Mumbai | F12: Corporate | G12: 60.5 | H12: 275 | I12: 720.05 | J12: 1 | K12: 720.05 | L12: UPI | N12: 23.7 | O12: Yes | P12: =IF(H12<(G12/60),"Impossible Speed","OK") -> OK
A13: TR0012 | B13: VH003 | C13: DR047 | D13: 2024-04-27 | E13: Mumbai | F13: Ride-Hailing | G13: 10.1 | H13: 48 | I13: 157.57 | J13: 2 | K13: 315.14 | L13: Corporate Account | M13: 4.9 | N13: 23.3 | O13: No | P13: =IF(H13<(G13/60),"Impossible Speed","OK") -> OK
A14: TR0013 | B14: VH025 | C14: DR047 | D14: 2024-02-23 | E14: Bangalore | F14: Shuttle | G14: 64.7 | H14: 257 | I14: 902.47 | J14: 1 | K14: 902.47 | L14: UPI | M14: 2.7 | N14: 1.5 | O14: No | P14: =IF(H14<(G14/60),"Impossible Speed","OK") -> OK
A15: TR0014 | B15: VH018 | C15: DR015 | D15: 2024-02-01 | E15: Mumbai | F15: Corporate | G15: 16.4 | H15: 89 | I15: 192.82 | J15: 1 | K15: 192.82 | L15: Card | M15: 3 | N15: 4.2 | O15: No | P15: =IF(H15<(G15/60),"Impossible Speed","OK") -> OK
A16: TR0015 | B16: VH030 | C16: DR037 | D16: 2024-04-08 | E16: Hyderabad | F16: Shuttle | G16: 14 | H16: 49 | I16: 221.3 | J16: 1.2 | K16: 265.56 | L16: Cash | M16: 2.7 | N16: 18.5 | O16: No | P16: =IF(H16<(G16/60),"Impossible Speed","OK") -> OK
A17: TR0016 | B17: VH026 | C17: DR007 | D17: 2024-02-07 | E17: Delhi | F17: Shuttle | G17: 10.8 | H17: 43 | I17: 230.84 | J17: 1 | K17: 230.84 | L17: Wallet | N17: 3.3 | O17: Yes | P17: =IF(H17<(G17/60),"Impossible Speed","OK") -> OK
A18: TR0017 | B18: VH021 | C18: DR035 | D18: 2024-01-03 | E18: Delhi | F18: Ride-Hailing | G18: 27.6 | H18: 114 | I18: 519.87 | J18: 1 | K18: 519.87 | L18: Wallet | M18: 5 | N18: 7.4 | O18: No | P18: =IF(H18<(G18/60),"Impossible Speed","OK") -> OK
A19: TR0018 | B19: VH026 | C19: DR030 | D19: 2024-03-14 | E19: Chennai | F19: Shuttle | G19: 11.8 | H19: 56 | I19: 212.74 | J19: 1.5 | K19: 319.11 | L19: Cash | M19: 2.6 | N19: 15 | O19: No | P19: =IF(H19<(G19/60),"Impossible Speed","OK") -> OK
A20: TR0019 | B20: VH017 | C20: DR034 | D20: 2024-02-02 | E20: Pune | F20: Corporate | G20: 55.6 | H20: 153 | I20: 973.97 | J20: 1.2 | K20: 1168.76 | L20: Cash | N20: 6.9 | O20: Yes | P20: =IF(H20<(G20/60),"Impossible Speed","OK") -> OK
A21: TR0020 | B21: VH020 | C21: DR003 | D21: 2024-01-14 | E21: Chennai | F21: Last-Mile | G21: 60.9 | H21: 193 | I21: 682.56 | J21: 1.2 | K21: 819.07 | L21: UPI | M21: 3.6 | N21: 23.3 | O21: No | P21: =IF(H21<(G21/60),"Impossible Speed","OK") -> OK
A22: TR0021 | B22: VH030 | C22: DR005 | D22: 2024-01-15 | E22: Pune | F22: Corporate | G22: 6.6 | H22: 28 | I22: 164.4 | J22: 1 | K22: 164.4 | L22: UPI | M22: 3.2 | N22: 11.5 | O22: No | P22: =IF(H22<(G22/60),"Impossible Speed","OK") -> OK
A23: TR0022 | B23: VH018 | C23: DR046 | D23: 2024-03-20 | E23: Chennai | F23: Corporate | G23: 44.1 | H23: 178 | I23: 448.48 | J23: 1 | K23: 448.48 | L23: Card | M23: 4.7 | N23: 18.8 | O23: No | P23: =IF(H23<(G23/60),"Impossible Speed","OK") -> OK
A24: TR0023 | B24: VH005 | C24: DR018 | D24: 2024-03-20 | E24: Delhi | F24: Last-Mile | G24: 14.8 | H24: 65 | I24: 240.7 | J24: 2 | K24: 481.4 | L24: Cash | M24: 4.1 | N24: 20.9 | O24: No | P24: =IF(H24<(G24/60),"Impossible Speed","OK") -> OK
A25: TR0024 | B25: VH002 | C25: DR001 | D25: 2024-03-25 | E25: Delhi | F25: Last-Mile | G25: 12.2 | H25: 57 | I25: 216.03 | J25: 1 | K25: 216.03 | L25: Cash | M25: 3.9 | N25: 21 | O25: No | P25: =IF(H25<(G25/60),"Impossible Speed","OK") -> OK
A26: TR0025 | B26: VH019 | C26: DR036 | D26: 2024-02-14 | E26: Delhi | F26: Corporate | G26: 21.4 | H26: 109 | I26: 405.39 | J26: 1 | K26: 405.39 | L26: UPI | M26: 4.2 | N26: 9.5 | O26: No | P26: =IF(H26<(G26/60),"Impossible Speed","OK") -> OK
A27: TR0026 | B27: VH018 | C27: DR027 | D27: 2024-02-08 | E27: Delhi | F27: Ride-Hailing | G27: 57.5 | H27: 163 | I27: 701.01 | J27: 1.2 | K27: 841.21 | L27: UPI | M27: 2.9 | N27: 17.8 | O27: No | P27: =IF(H27<(G27/60),"Impossible Speed","OK") -> OK
A28: TR0027 | B28: VH013 | C28: DR003 | D28: 2024-04-08 | E28: Delhi | F28: Shuttle | G28: 24 | H28: 117 | I28: 295.5 | J28: 1.8 | K28: 531.9 | L28: UPI | M28: 3.3 | N28: 21.7 | O28: No | P28: =IF(H28<(G28/60),"Impossible Speed","OK") -> OK
A29: TR0028 | B29: VH025 | C29: DR018 | D29: 2024-03-21 | E29: Pune | F29: Shuttle | G29: 44.8 | H29: 198 | I29: 420.77 | J29: 1 | K29: 420.77 | L29: UPI | N29: 24.1 | O29: Yes | P29: =IF(H29<(G29/60),"Impossible Speed","OK") -> OK
A30: TR0029 | B30: VH009 | C30: DR003 | D30: 2024-01-20 | E30: Hyderabad | F30: Last-Mile | G30: 47.9 | H30: 164 | I30: 678.17 | J30: 1.2 | K30: 813.8 | L30: Corporate Account | M30: 3.1 | N30: 18 | O30: No | P30: =IF(H30<(G30/60),"Impossible Speed","OK") -> OK
A31: TR0030 | B31: VH001 | C31: DR034 | D31: 2024-02-12 | E31: Hyderabad | F31: Corporate | G31: 61.8 | H31: 283 | I31: 954.37 | J31: 1 | K31: 954.37 | L31: Card | N31: 8.4 | O31: Yes | P31: =IF(H31<(G31/60),"Impossible Speed","OK") -> OK
A32: TR0031 | B32: VH014 | C32: DR021 | D32: 2024-04-23 | E32: Bangalore | F32: Ride-Hailing | G32: 14.1 | H32: 65 | I32: 268.29 | J32: 1 | K32: 268.29 | L32: Corporate Account | N32: 8.2 | O32: Yes | P32: =IF(H32<(G32/60),"Impossible Speed","OK") -> OK
A33: TR0032 | B33: VH018 | C33: DR001 | D33: 2024-03-10 | E33: Delhi | F33: Shuttle | G33: 51.5 | H33: 201 | I33: 689.52 | J33: 1.8 | K33: 1241.14 | L33: UPI | N33: 12.4 | O33: Yes | P33: =IF(H33<(G33/60),"Impossible Speed","OK") -> OK
A34: TR0033 | B34: VH029 | C34: DR048 | D34: 2024-02-22 | E34: Mumbai | F34: Last-Mile | G34: 34.5 | H34: 140 | I34: 608.36 | J34: 2 | K34: 1216.72 | L34: UPI | M34: 3.1 | N34: 5.8 | O34: No | P34: =IF(H34<(G34/60),"Impossible Speed","OK") -> OK
A35: TR0034 | B35: VH001 | C35: DR003 | D35: 2024-02-16 | E35: Pune | F35: Corporate | G35: 30.7 | H35: 145 | I35: 516.13 | J35: 1.2 | K35: 619.36 | L35: Wallet | M35: 3.1 | N35: 16.7 | O35: No | P35: =IF(H35<(G35/60),"Impossible Speed","OK") -> OK
A36: TR0035 | B36: VH001 | C36: DR049 | D36: 2024-01-25 | E36: Hyderabad | F36: Ride-Hailing | G36: 13.1 | H36: 71 | I36: 161.38 | J36: 1 | K36: 161.38 | L36: Cash | M36: 2.8 | N36: 12.2 | O36: No | P36: =IF(H36<(G36/60),"Impossible Speed","OK") -> OK
A37: TR0036 | B37: VH017 | C37: DR036 | D37: 2024-03-25 | E37: Hyderabad | F37: Shuttle | G37: 54.3 | H37: 214 | I37: 888.2 | J37: 1.2 | K37: 1065.84 | L37: Wallet | M37: 4.4 | N37: 21.2 | O37: No | P37: =IF(H37<(G37/60),"Impossible Speed","OK") -> OK
A38: TR0037 | B38: VH009 | C38: DR050 | D38: 2024-04-21 | E38: Delhi | F38: Last-Mile | G38: 29.7 | H38: 125 | I38: 387.35 | J38: 1.5 | K38: 581.03 | L38: Cash | M38: 2.9 | N38: 10.2 | O38: No | P38: =IF(H38<(G38/60),"Impossible Speed","OK") -> OK
A39: TR0038 | B39: VH005 | C39: DR046 | D39: 2024-02-03 | E39: Hyderabad | F39: Shuttle | G39: 22.8 | H39: 84 | I39: 422.3 | J39: 1.2 | K39: 506.76 | L39: Corporate Account | M39: 4.6 | N39: 19.4 | O39: No | P39: =IF(H39<(G39/60),"Impossible Speed","OK") -> OK
A40: TR0039 | B40: VH013 | C40: DR031 | D40: 2024-01-12 | E40: Bangalore | F40: Shuttle | G40: 55.8 | H40: 257 | I40: 913.51 | J40: 1.5 | K40: 1370.26 | L40: Corporate Account | M40: 3.7 | N40: 7.6 | O40: No | P40: =IF(H40<(G40/60),"Impossible Speed","OK") -> OK
...

Sheet Driver_Data
A1: Driver_ID | B1: Driver_Name | C1: Age | D1: City | E1: License_Type | F1: Experience_Years | G1: Total_Trips | H1: Avg_Rating | I1: Monthly_Salary_INR | J1: Incentive_INR | K1: Violations | L1: Status | M1: Join_Date
A2: DR001 | B2: Rajesh Kumar | C2: 49 | D2: Hyderabad | E2: HMV | F2: 20 | G2: 1564 | H2: 3.5 | I2: 20000 | J2: 6079 | K2: 4 | L2: Terminated | M2: 2021-09-22
A3: DR002 | B3: Amit Sharma | C3: 29 | D3: Pune | E3: LMV | F3: 7 | G3: 3554 | H3: 4.4 | I3: 28000 | J3: 1734 | K3: 5 | L3: Active | M3: 2023-04-05
A4: DR003 | B4: Suresh Patel | C4: 53 | D4: Chennai | E4: HMV | F4: 19 | G4: 2875 | H4: 3.2 | I4: 30000 | J4: 4230 | K4: 1 | L4: Active | M4: 2020-07-02
A5: DR004 | B5: Vikram Singh | C5: 41 | D5: Pune | E5: LMV | F5: 14 | G5: 1769 | H5: 3.7 | I5: 28000 | J5: 647 | K5: 8 | L5: Active | M5: 2022-08-02
A6: DR005 | B6: Anil Verma | C6: 46 | D6: Delhi | E6: HMV | F6: 6 | G6: 3718 | H6: 4.2 | I6: 20000 | J6: 7551 | K6: 2 | L6: Active | M6: 2018-01-06
A7: DR006 | B7: Deepak Yadav | C7: 54 | D7: Chennai | E7: LMV | F7: 3 | G7: 3585 | H7: 4.3 | I7: 20000 | J7: 2478 | K7: 0 | L7: Active | M7: 2020-03-17
A8: DR007 | B8: Sanjay Gupta | C8: 49 | D8: Delhi | E8: LMV | F8: 7 | G8: 3728 | H8: 3.5 | I8: 25000 | J8: 6601 | K8: 2 | L8: Active | M8: 2023-08-02
A9: DR008 | B9: Manoj Tiwari | C9: 32 | D9: Chennai | E9: HMV | F9: 20 | G9: 3444 | H9: 3.2 | I9: 18000 | J9: 1149 | K9: 2 | L9: Active | M9: 2021-03-07
A10: DR009 | B10: Rahul Das | C10: 44 | D10: Hyderabad | E10: HMV | F10: 9 | G10: 1060 | H10: 4.7 | I10: 22000 | J10: 1488 | K10: 1 | L10: On Leave | M10: 2020-01-19
A11: DR010 | B11: Prakash Joshi | C11: 27 | D11: Bangalore | E11: HMV | F11: 13 | G11: 3369 | H11: 3.7 | I11: 25000 | J11: 3088 | K11: 5 | L11: On Leave | M11: 2018-03-02
A12: DR011 | B12: Ravi Shankar | C12: 47 | D12: Chennai | E12: LMV | F12: 15 | G12: 1985 | H12: 3.6 | I12: 30000 | J12: 1808 | K12: 4 | L12: Active | M12: 2023-12-11
A13: DR012 | B13: Gopal Mishra | C13: 37 | D13: Chennai | E13: HMV | F13: 13 | G13: 2527 | H13: 3.9 | I13: 18000 | J13: 7060 | K13: 6 | L13: Active | M13: 2018-09-10
... A51: DR050 | B51: Akhil Jain | C51: 49 | D51: Pune | E51: LMV | F51: 1 | G51: 3557 | H51: 3.2 | I51: 25000 | J51: 853 | K51: 0 | L51: Active | M51: 2018-04-10

Sheet Maintenance_Data
A1: Maintenance_ID | B1: Vehicle_ID | C1: Make | D1: Maintenance_Type | E1: Date | F1: Cost_INR | G1: Downtime_Days | H1: Vendor | I1: Parts_Replaced | J1: Next_Due_Date | K1: Priority
A2: MN0001 | B2: VH026 | C2: =VLOOKUP(B2,Fleet_Vehicle_Data!$A:$B,2,FALSE) -> BYD | D2: Battery Replacement | E2: 2024-03-07 | F2: 11202 | G2: 3 | H2: QuickServ Auto | I2: Wiper Blades | J2: 2024-08-05 | K2: Low
A3: MN0002 | B3: VH028 | C3: =VLOOKUP(B3,Fleet_Vehicle_Data!$A:$B,2,FALSE) -> Maruti | D3: Battery Replacement | E3: 2024-01-27 | F3: 43094 | G3: 5 | H3: FleetFix Solutions | I3: Coolant | J3: 2024-11-06 | K3: High
A4: MN0003 | B4: VH011 | C4: =VLOOKUP(B4,Fleet_Vehicle_Data!$A:$B,2,FALSE) -> Hyundai | D4: Brake Repair | E4: 2024-01-18 | F4: 35153 | G4: 15 | H4: FleetFix Solutions | I4: Spark Plugs | J4: 2024-08-03 | K4: Low
A5: MN0004 | B5: VH028 | C5: =VLOOKUP(B5,Fleet_Vehicle_Data!$A:$B,2,FALSE) -> Maruti | D5: Tire Replacement | E5: 2024-04-20 | F5: 31840 | G5: 2 | H5: AutoCare Pro | I5: Spark Plugs | J5: 2024-10-28 | K5: Low
A6: MN0005 | B6: VH004 | C6: =VLOOKUP(B6,Fleet_Vehicle_Data!$A:$B,2,FALSE) -> Tata | D6: Suspension Repair | E6: 2024-04-27 | F6: 4030 | G6: 3 | H6: QuickServ Auto | I6: Wiper Blades | J6: 2024-06-12 | K6: Low
A7: MN0006 | B7: VH027 | C7: =VLOOKUP(B7,Fleet_Vehicle_Data!$A:$B,2,FALSE) -> Mahindra | D7: Electrical Issue | E7: 2024-02-08 | F7: 25984 | G7: 12 | H7: SpeedyRepair | I7: Air Filter | J7: 2024-11-01 | K7: Low
A8: MN0007 | B8: VH002 | C8: =VLOOKUP(B8,Fleet_Vehicle_Data!$A:$B,2,FALSE) -> Hyundai | D8: Body Repair | E8: 2024-01-24 | F8: 16433 | G8: 13 | H8: AutoCare Pro | I8: Battery | J8: 2024-12-02 | K8: Critical
A9: MN0008 | B9: VH027 | C9: =VLOOKUP(B9,Fleet_Vehicle_Data!$A:$B,2,FALSE) -> Mahindra | D9: Brake Repair | E9: 2024-02-10 | F9: 24137 | G9: 0 | H9: MechMaster | I9: Tires (Set of 4) | J9: 2024-11-19 | K9: Low
A10: MN0009 | B10: VH002 | C10: =VLOOKUP(B10,Fleet_Vehicle_Data!$A:$B,2,FALSE) -> Hyundai | D10: Body Repair | E10: 2024-02-25 | F10: 37376 | G10: 0 | H10: SpeedyRepair | I10: Oil Filter | J10: 2024-08-03 | K10: Critical
A11: MN0010 | B11: VH004 | C11: =VLOOKUP(B11,Fleet_Vehicle_Data!$A:$B,2,FALSE) -> Tata | D11: Electrical Issue | E11: 2024-04-04 | F11: 39827 | G11: 4 | H11: FleetFix Solutions | I11: Battery | J11: 2024-08-25 | K11: Low
A12: MN0011 | B12: VH006 | C12: =VLOOKUP(B12,Fleet_Vehicle_Data!$A:$B,2,FALSE) -> Honda | D12: Engine Overhaul | E12: 2024-02-01 | F12: 2748 | G12: 7 | H12: SpeedyRepair | I12: Coolant | J12: 2024-11-19 | K12: Critical
A13: MN0012 | B13: VH016 | C13: =VLOOKUP(B13,Fleet_Vehicle_Data!$A:$B,2,FALSE) -> Tata | D13: Oil Change | E13: 2024-03-20 | F13: 37845 | G13: 3 | H13: MechMaster | I13: Belt Assembly | J13: 2024-11-10 | K13: High
... A61: MN0060 | B61: VH022 | C61: =VLOOKUP(B61,Fleet_Vehicle_Data!$A:$B,2,FALSE) -> Maruti | D61: Oil Change | E61: 2024-03-24 | F61: 18338 | G61: 0 | H61: MechMaster | I61: NA | J61: 2024-11-14 | K61: Medium

Sheet Revenue_Summary_Raw
A1: Month | B1: City | C1: Service_Type | D1: Total_Trips | E1: Completed_Trips | F1: Cancelled_Trips | G1: Revenue_INR | H1: Fuel_Cost_INR | I1: Maintenance_Cost_INR | J1: Driver_Cost_INR | K1: Profit_INR
A2: January | B2: Mumbai | C2: Corporate | D2: 96 | E2: 88 | F2: 8 | G2: 30797 | H2: 8035 | I2: 4131 | J2: 9611 | K2: 8822
A3: January | B3: Mumbai | C3: Ride-Hailing | D3: 230 | E3: 196 | F3: 34 | G3: 180685 | H3: 53274 | I3: 21007 | J3: 50788 | K3: 55504
A4: January | B4: Mumbai | C4: Last-Mile | D4: 257 | E4: 232 | F4: 25 | G4: 213230 | H4: 45702 | I4: 22052 | J4: 62827 | K4: 82782
A5: January | B5: Mumbai | C5: Shuttle | D5: 71 | E5: 65 | F5: 6 | G5: 46342 | H5: 7052 | I5: 4470 | J5: 10824 | K5: 23875
A6: January | B6: Delhi | C6: Corporate | D6: 95 | E6: 82 | F6: 13 | G6: 69232 | H6: 14832 | I6: 5031 | J6: 15978 | K6: 33061
A7: January | B7: Delhi | C7: Ride-Hailing | D7: 219 | E7: 188 | F7: 31 | G7: 39163 | H7: 10726 | I7: 3564 | J7: 9740 | K7: 15252
A8: January | B8: Delhi | C8: Last-Mile | D8: 173 | E8: 154 | F8: 19 | G8: 57777 | H8: 10089 | I8: 4675 | J8: 12960 | K8: 29762
A9: January | B9: Delhi | C9: Shuttle | D9: 375 | E9: 362 | F9: 13 | G9: 371876 | H9: 95857 | I9: 49299 | J9: 107055 | K9: 119906
A10: January | B10: Bangalore | C10: Corporate | D10: 254 | E10: 244 | F10: 10 | G10: 110851 | H10: 30196 | I10: 13289 | J10: 27129 | K10: 40007
A11: January | B11: Bangalore | C11: Ride-Hailing | D11: 92 | E11: 81 | F11: 11 | G11: 80220 | H11: 18011 | I11: 4561 | J11: 19199 | K11: 38304
A12: January | B12: Bangalore | C12: Last-Mile | D12: 193 | E12: 181 | F12: 12 | G12: 107202 | H12: 22884 | I12: 11687 | J12: 31661 | K12: 40527
A13: January | B13: Bangalore | C13: Shuttle | D13: 171 | E13: 146 | F13: 25 | G13: 135331 | H13: 27512 | I13: 12431 | J13: 41376 | K13: 54074
... A97: April | B97: Chennai | C97: Shuttle | D97: 262 | E97: 254 | F97: 8 | G97: 104818 | H97: 27984 | I97: 7713 | J97: 24756 | K97: 44136

Sheet Analysis_A1_A2
A1: Task A1 – Total vehicles per City | D1: Task A1 – Vehicles with Rating > 4.0 per City
A2: City | B2: Total Vehicles | D2: City | E2: Total Vehicles
A3: Mumbai | B3: =COUNTIF(Fleet_Vehicle_Data!$I:$I,A3) -> 5 | D3: Mumbai | E3: =COUNTIFS(Fleet_Vehicle_Data!$I:$I,D3,Fleet_Vehicle_Data!$O:$O,">4") -> 3
A4: Delhi | B4: =COUNTIF(Fleet_Vehicle_Data!$I:$I,A4) -> 5 | D4: Delhi | E4: =COUNTIFS(Fleet_Vehicle_Data!$I:$I,D4,Fleet_Vehicle_Data!$O:$O,">4") -> 5
A5: Bangalore | B5: =COUNTIF(Fleet_Vehicle_Data!$I:$I,A5) -> 5 | D5: Bangalore | E5: =COUNTIFS(Fleet_Vehicle_Data!$I:$I,D5,Fleet_Vehicle_Data!$O:$O,">4") -> 1
A6: Hyderabad | B6: =COUNTIF(Fleet_Vehicle_Data!$I:$I,A6) -> 5 | D6: Hyderabad | E6: =COUNTIFS(Fleet_Vehicle_Data!$I:$I,D6,Fleet_Vehicle_Data!$O:$O,">4") -> 5
A7: Pune | B7: =COUNTIF(Fleet_Vehicle_Data!$I:$I,A7) -> 5 | D7: Pune | E7: =COUNTIFS(Fleet_Vehicle_Data!$I:$I,D7,Fleet_Vehicle_Data!$O:$O,">4") -> 1
A8: Chennai | B8: =COUNTIF(Fleet_Vehicle_Data!$I:$I,A8) -> 5 | D8: Chennai | E8: =COUNTIFS(Fleet_Vehicle_Data!$I:$I,D8,Fleet_Vehicle_Data!$O:$O,">4") -> 4
A10: Task A1 – Average Mileage per Fuel Type | D10: Task A1 – Total Monthly Revenue by Service Type
A11: Fuel Type | B11: Average Mileage | D11: Service Type | E11: Total Revenue
A12: Petrol | B12: =AVERAGEIF(Fleet_Vehicle_Data!$F:$F,A12,Fleet_Vehicle_Data!$K:$K) -> 17.033333 | D12: Corporate | E12: =SUMIF(Fleet_Vehicle_Data!$J:$J,D12,Fleet_Vehicle_Data!$M:$M) -> 103200
A13: Diesel | B13: =AVERAGEIF(Fleet_Vehicle_Data!$F:$F,A13,Fleet_Vehicle_Data!$K:$K) -> 12.677778 | D13: Ride-Hailing | E13: =SUMIF(Fleet_Vehicle_Data!$J:$J,D13,Fleet_Vehicle_Data!$M:$M) -> 97500
A14: CNG | B14: =AVERAGEIF(Fleet_Vehicle_Data!$F:$F,A14,Fleet_Vehicle_Data!$K:$K) -> 22.64 | D14: Last-Mile | E14: =SUMIF(Fleet_Vehicle_Data!$J:$J,D14,Fleet_Vehicle_Data!$M:$M) -> 74800
A15: Electric | B15: =AVERAGEIF(Fleet_Vehicle_Data!$F:$F,A15,Fleet_Vehicle_Data!$K:$K) -> 0 | D15: Shuttle | E15: =SUMIF(Fleet_Vehicle_Data!$J:$J,D15,Fleet_Vehicle_Data!$M:$M) -> 47000
A19: Task A2 – Vehicle Lookup
A20: Vehicle ID | B20: VH025
A21: Make | B21: =IFERROR(VLOOKUP($B$20,Fleet_Vehicle_Data!$A$2:$O$31,2,FALSE),"") -> Tata
A22: Model | B22: =IFERROR(VLOOKUP($B$20,Fleet_Vehicle_Data!$A$2:$O$31,3,FALSE),"") -> Altroz
A23: City | B23: =IFERROR(VLOOKUP($B$20,Fleet_Vehicle_Data!$A$2:$O$31,9,FALSE),"") -> Mumbai
A24: Status | B24: =IFERROR(VLOOKUP($B$20,Fleet_Vehicle_Data!$A$2:$O$31,8,FALSE),"") -> Under Maintenance
A25: Monthly Revenue | B25: =IFERROR(VLOOKUP($B$20,Fleet_Vehicle_Data!$A$2:$O$31,13,FALSE),"") -> 12200

Sheet Analysis_A3
A1: Task A3 – Trip Performance Analysis by City
A2: City | B2: Avg Fare/km | C2: Cancellation % | D2: Avg Customer Rating | E2: Surge Revenue
A3: Bangalore | B3: =SUMIFS(Trip_Data!$K:$K,Trip_Data!$E:$E,A3)/SUMIFS(Trip_Data!$G:$G,Trip_Data!$E:$E,A3) -> 21.529793 | C3: =COUNTIFS(Trip_Data!$E:$E,A3,Trip_Data!$O:$O,"Yes")/COUNTIF(Trip_Data!$E:$E,A3) -> 0.21428571 | D3: =AVERAGEIFS(Trip_Data!$M:$M,Trip_Data!$E:$E,A3) -> 3.4727273 | E3: =SUMIFS(Trip_Data!$K:$K,Trip_Data!$E:$E,A3,Trip_Data!$J:$J,">1") -> 6799.66
A4: Chennai | B4: =SUMIFS(Trip_Data!$K:$K,Trip_Data!$E:$E,A4)/SUMIFS(Trip_Data!$G:$G,Trip_Data!$E:$E,A4) -> 19.537711 | C4: =COUNTIFS(Trip_Data!$E:$E,A4,Trip_Data!$O:$O,"Yes")/COUNTIF(Trip_Data!$E:$E,A4) -> 0.15 | D4: =AVERAGEIFS(Trip_Data!$M:$M,Trip_Data!$E:$E,A4) -> 3.7764706 | E4: =SUMIFS(Trip_Data!$K:$K,Trip_Data!$E:$E,A4,Trip_Data!$J:$J,">1") -> 9011.9
A5: Delhi | B5: =SUMIFS(Trip_Data!$K:$K,Trip_Data!$E:$E,A5)/SUMIFS(Trip_Data!$G:$G,Trip_Data!$E:$E,A5) -> 19.725931 | C5: =COUNTIFS(Trip_Data!$E:$E,A5,Trip_Data!$O:$O,"Yes")/COUNTIF(Trip_Data!$E:$E,A5) -> 0.2173913 | D5: =AVERAGEIFS(Trip_Data!$M:$M,Trip_Data!$E:$E,A5) -> 3.8777778 | E5: =SUMIFS(Trip_Data!$K:$K,Trip_Data!$E:$E,A5,Trip_Data!$J:$J,">1") -> 10179.33
A6: Hyderabad | B6: =SUMIFS(Trip_Data!$K:$K,Trip_Data!$E:$E,A6)/SUMIFS(Trip_Data!$G:$G,Trip_Data!$E:$E,A6) -> 20.197524 | C6: =COUNTIFS(Trip_Data!$E:$E,A6,Trip_Data!$O:$O,"Yes")/COUNTIF(Trip_Data!$E:$E,A6) -> 0.10526316 | D6: =AVERAGEIFS(Trip_Data!$M:$M,Trip_Data!$E:$E,A6) -> 3.7235294 | E6: =SUMIFS(Trip_Data!$K:$K,Trip_Data!$E:$E,A6,Trip_Data!$J:$J,">1") -> 9391.16
A7: Mumbai | B7: =SUMIFS(Trip_Data!$K:$K,Trip_Data!$E:$E,A7)/SUMIFS(Trip_Data!$G:$G,Trip_Data!$E:$E,A7) -> 21.610586 | C7: =COUNTIFS(Trip_Data!$E:$E,A7,Trip_Data!$O:$O,"Yes")/COUNTIF(Trip_Data!$E:$E,A7) -> 0.33333333 | D7: =AVERAGEIFS(Trip_Data!$M:$M,Trip_Data!$E:$E,A7) -> 3.775 | E7: =SUMIFS(Trip_Data!$K:$K,Trip_Data!$E:$E,A7,Trip_Data!$J:$J,">1") -> 6667.78
A8: Pune | B8: =SUMIFS(Trip_Data!$K:$K,Trip_Data!$E:$E,A8)/SUMIFS(Trip_Data!$G:$G,Trip_Data!$E:$E,A8) -> 18.331609 | C8: =COUNTIFS(Trip_Data!$E:$E,A8,Trip_Data!$O:$O,"Yes")/COUNTIF(Trip_Data!$E:$E,A8) -> 0.25 | D8: =AVERAGEIFS(Trip_Data!$M:$M,Trip_Data!$E:$E,A8) -> 3.9333333 | E8: =SUMIFS(Trip_Data!$K:$K,Trip_Data!$E:$E,A8,Trip_Data!$J:$J,">1") -> 5280.96

Sheet Cleaned_Revenue
A1: Month | B1: City | C1: Service_Type | D1: Total_Trips | E1: Completed_Trips | F1: Cancelled_Trips | G1: Revenue_INR | H1: Fuel_Cost_INR | I1: Maintenance_Cost_INR | J1: Driver_Cost_INR | K1: Profit_INR | L1: Recalculated_Profit | M1: Profit_Margin_% | N1: Error_Flag
A2: January | B2: Mumbai | C2: Corporate | D2: 96 | E2: 88 | F2: 8 | G2: 30797 | H2: 8035 | I2: 4131 | J2: 9611 | K2: 8822 | L2: =G2-H2-I2-J2 -> 9020 | M2: =L2/G2 -> 0.29288567 | N2: =IF(ABS(K2-L2)<=1,"OK","ERROR") -> ERROR
A3: January | B3: Mumbai | C3: Ride-Hailing | D3: 230 | E3: 196 | F3: 34 | G3: 180685 | H3: 53274 | I3: 21007 | J3: 50788 | K3: 55504 | L3: =G3-H3-I3-J3 -> 55616 | M3: =L3/G3 -> 0.3078064 | N3: =IF(ABS(K3-L3)<=1,"OK","ERROR") -> ERROR
A4: January | B4: Mumbai | C4: Last-Mile | D4: 257 | E4: 232 | F4: 25 | G4: 213230 | H4: 45702 | I4: 22052 | J4: 62827 | K4: 82782 | L4: =G4-H4-I4-J4 -> 82649 | M4: =L4/G4 -> 0.38760493 | N4: =IF(ABS(K4-L4)<=1,"OK","ERROR") -> ERROR
A5: January | B5: Mumbai | C5: Shuttle | D5: 71 | E5: 65 | F5: 6 | G5: 46342 | H5: 7052 | I5: 4470 | J5: 10824 | K5: 23875 | L5: =G5-H5-I5-J5 -> 23996 | M5: =L5/G5 -> 0.51780243 | N5: =IF(ABS(K5-L5)<=1,"OK","ERROR") -> ERROR
A6: January | B6: Delhi | C6: Corporate | D6: 95 | E6: 82 | F6: 13 | G6: 69232 | H6: 14832 | I6: 5031 | J6: 15978 | K6: 33061 | L6: =G6-H6-I6-J6 -> 33391 | M6: =L6/G6 -> 0.48230587 | N6: =IF(ABS(K6-L6)<=1,"OK","ERROR") -> ERROR
A7: January | B7: Delhi | C7: Ride-Hailing | D7: 219 | E7: 188 | F7: 31 | G7: 39163 | H7: 10726 | I7: 3564 | J7: 9740 | K7: 15252 | L7: =G7-H7-I7-J7 -> 15133 | M7: =L7/G7 -> 0.38641064 | N7: =IF(ABS(K7-L7)<=1,"OK","ERROR") -> ERROR
A8: January | B8: Delhi | C8: Last-Mile | D8: 173 | E8: 154 | F8: 19 | G8: 57777 | H8: 10089 | I8: 4675 | J8: 12960 | K8: 29762 | L8: =G8-H8-I8-J8 -> 30053 | M8: =L8/G8 -> 0.52015508 | N8: =IF(ABS(K8-L8)<=1,"OK","ERROR") -> ERROR
A9: January | B9: Delhi | C9: Shuttle | D9: 375 | E9: 362 | F9: 13 | G9: 371876 | H9: 95857 | I9: 49299 | J9: 107055 | K9: 119906 | L9: =G9-H9-I9-J9 -> 119665 | M9: =L9/G9 -> 0.32178737 | N9: =IF(ABS(K9-L9)<=1,"OK","ERROR") -> ERROR
A10: January | B10: Bangalore | C10: Corporate | D10: 254 | E10: 244 | F10: 10 | G10: 110851 | H10: 30196 | I10: 13289 | J10: 27129 | K10: 40007 | L10: =G10-H10-I10-J10 -> 40237 | M10: =L10/G10 -> 0.36298274 | N10: =IF(ABS(K10-L10)<=1,"OK","ERROR") -> ERROR
A11: January | B11: Bangalore | C11: Ride-Hailing | D11: 92 | E11: 81 | F11: 11 | G11: 80220 | H11: 18011 | I11: 4561 | J11: 19199 | K11: 38304 | L11: =G11-H11-I11-J11 -> 38449 | M11: =L11/G11 -> 0.47929444 | N11: =IF(ABS(K11-L11)<=1,"OK","ERROR") -> ERROR
A12: January | B12: Bangalore | C12: Last-Mile | D12: 193 | E12: 181 | F12: 12 | G12: 107202 | H12: 22884 | I12: 11687 | J12: 31661 | K12: 40527 | L12: =G12-H12-I12-J12 -> 40970 | M12: =L12/G12 -> 0.38217571 | N12: =IF(ABS(K12-L12)<=1,"OK","ERROR") -> ERROR
A13: January | B13: Bangalore | C13: Shuttle | D13: 171 | E13: 146 | F13: 25 | G13: 135331 | H13: 27512 | I13: 12431 | J13: 41376 | K13: 54074 | L13: =G13-H13-I13-J13 -> 54012 | M13: =L13/G13 -> 0.39911033 | N13: =IF(ABS(K13-L13)<=1,"OK","ERROR") -> ERROR
... A97: April | B97: Chennai | C97: Shuttle | D97: 262 | E97: 254 | F97: 8 | G97: 104818 | H97: 27984 | I97: 7713 | J97: 24756 | K97: 44136 | L97: =G97-H97-I97-J97 -> 44365 | M97: =L97/G97 -> 0.42325746 | N97: =IF(ABS(K97-L97)<=1,"OK","ERROR") -> ERROR
C100: =SUM(G:G) -> 16967177 | D100: =SUM(H:H) -> 3910162 | E100: =SUM(I:I) -> 1664580 | F100: =SUM(J:J) -> 4624231

Sheet Validation_Report
A1: Validation Report
A3: High Odometer Vehicles (>80,000 km)
A4: Vehicle_ID | B4: Make | C4: Model | D4: Year | E4: Body_Type | F4: Fuel_Type | G4: Odometer_km | H4: Status | I4: City | J4: Service_Type | K4: Mileage_kmpl | L4: Last_Service_Date | M4: Monthly_Revenue_INR | N4: Insurance_Premium_INR | O4: Driver_Rating
A5: VH013 | B5: Mahindra | C5: Scorpio | D5: 2019 | E5: SUV | F5: Diesel | G5: 89000 | H5: Under Maintenance | I5: Mumbai | J5: Corporate | K5: 11.5 | L5: 2023-08-10 | M5: 18500 | N5: 1150 | O5: 3.5
A6: VH027 | B6: Mahindra | C6: Bolero | D6: 2019 | E6: SUV | F6: Diesel | G6: 95000 | H6: Active | I6: Bangalore | J6: Last-Mile | K6: 10.5 | L6: 2023-06-20 | M6: 19800 | N6: 780 | O6: 3.4
A8: Drivers Requiring Review
A9: City | B9: License_Type | C9: Experience_Years | D9: Total_Trips | E9: Avg_Rating | F9: Monthly_Salary_INR | G9: Incentive_INR | H9: Violations | I9: Status | J9: Join_Date
A10: Pune | B10: LMV | C10: 14 | D10: 1769 | E10: 3.7 | F10: 28000 | G10: 647 | H10: 8 | I10: Active | J10: 2022-08-02
A11: Chennai | B11: HMV | C11: 13 | D11: 2527 | E11: 3.9 | F11: 18000 | G11: 7060 | H11: 6 | I11: Active | J11: 2018-09-10
A12: Delhi | B12: LMV | C12: 4 | D12: 2619 | E12: 3.2 | F12: 18000 | G12: 7689 | H12: 6 | I12: Active | J12: 2020-09-21
A13: Hyderabad | B13: HMV | C13: 12 | D13: 2149 | E13: 3.4 | F13: 25000 | G13: 4581 | H13: 6 | I13: Active | J13: 2021-10-21
A14: Mumbai | B14: LMV | C14: 6 | D14: 3529 | E14: 3.8 | F14: 18000 | G14: 622 | H14: 8 | I14: Active | J14: 2020-12-06
A16: Electric Vehicle Validation
A17: Vehicle_ID | B17: Make | C17: Model | D17: Year | E17: Body_Type | F17: Fuel_Type | G17: Odometer_km | H17: Status | I17: City | J17: Service_Type | K17: Mileage_kmpl | L17: Last_Service_Date | M17: Monthly_Revenue_INR | N17: Insurance_Premium_INR | O17: Driver_Rating
A18: No inconsistencies found.
A20: Impossible Speed Trips
A21: Trip_ID | B21: Vehicle_ID | C21: Driver_ID | D21: Trip_Date | E21: City | F21: Service_Type | G21: Distance_km | H21: Duration_min | I21: Base_Fare_INR | J21: Surge_Multiplier | K21: Total_Fare_INR | L21: Payment_Mode | M21: Customer_Rating | N21: Wait_Time_min | O21: Cancelled | P21: Validation
A22: No inconsistencies found.

Sheet Pivot_Analysis
A1: PIVOT TABLES & CHARTS
A3: Revenue by City and Month (with Grand Totals)
A4: Sum of Revenue_INR | B4: Column Labels
A5: Row Labels | B5: January | C5: February | D5: March | E5: April | F5: Grand Total
A6: Bangalore | B6: 433604 | C6: 864165 | D6: 822597 | E6: 1004529 | F6: 3124895
A7: Chennai | B7: 1057346 | C7: 450498 | D7: 306400 | E7: 866657 | F7: 2680901
A8: Delhi | B8: 538048 | C8: 1024075 | D8: 617248 | E8: 624249 | F8: 2803620
A9: Hyderabad | B9: 457659 | C9: 542406 | D9: 903625 | E9: 1060503 | F9: 2964193
A10: Mumbai | B10: 471054 | C10: 942327 | D10: 722160 | E10: 643684 | F10: 2779225
A11: Pune | B11: 807403 | C11: 562598 | D11: 674868 | E11: 569474 | F11: 2614343
A12: Grand Total | B12: 3765114 | C12: 4386069 | D12: 4046898 | E12: 4769096 | F12: 16967177
A15: Average Rating by Service Type and City
A16: Average of Customer_Rating | B16: Column Labels
A17: Row Labels | B17: Bangalore | C17: Chennai | D17: Delhi | E17: Hyderabad | F17: Mumbai | G17: Pune | H17: Grand Total
A18: Corporate | B18: 3.3 | C18: 4.0833333 | D18: 4.1571429 | E18: 4.22 | F18: 3.825 | G18: 3.725 | H18: 3.9821429
A19: Last-Mile | B19: 4.2 | C19: 3.74 | D19: 3.8 | E19: 3.575 | F19: 3.45 | G19: 3.8 | H19: 3.7210526
A20: Ride-Hailing | B20: 3.35 | C20: 3.4333333 | D20: 3.95 | E20: 3.6 | F20: 4.9 | G20: 4.6 | H20: 3.7153846
A21: Shuttle | B21: 3.5 | C21: 3.5666667 | D21: 3.45 | E21: 3.45 | F21: 3.1 | G21: 4.15 | H21: 3.53
A22: Grand Total | B22: 3.4727273 | C22: 3.7764706 | D22: 3.8777778 | E22: 3.7235294 | F22: 3.775 | G22: 3.9333333 | H22: 3.76375
A26: Maintenance Cost by Vehicle Make and Maintenance Type
A27: Sum of Cost_INR | B27: Column Labels
A28: Row Labels | B28: Battery Replacement | C28: Body Repair | D28: Brake Repair | E28: Electrical Issue | F28: Engine Overhaul | G28: Oil Change | H28: Scheduled Service | I28: Suspension Repair | J28: Tire Replacement | K28: Grand Total
A29: BYD | B29: 11202 | C29: 21325 | E29: 36231 | G29: 22311 | J29: 35941 | K29: 127010
A30: Honda | B30: 29399 | C30: 39539 | E30: 7251 | F30: 2748 | H30: 19147 | K30: 98084
A31: Hyundai | C31: 75936 | D31: 35153 | F31: 43295 | J31: 45072 | K31: 199456
A32: Kia | B32: 16764 | E32: 58338 | F32: 3314 | I32: 30254 | K32: 108670
A33: Mahindra | D33: 65045 | E33: 50940 | K33: 115985
A34: Maruti | B34: 97696 | C34: 22421 | D34: 4197 | E34: 25871 | F34: 30668 | G34: 18338 | H34: 58821 | I34: 37379 | J34: 52369 | K34: 347760
A35: MG | B35: 14078 | F35: 37320 | J35: 5269 | K35: 56667
A36: Tata | C36: 24428 | E36: 71956 | G36: 37845 | H36: 47082 | I36: 63418 | K36: 244729
A37: Toyota | B37: 70929 | C37: 26837 | D37: 64550 | E37: 19702 | G37: 63718 | K37: 245736
A38: Grand Total | B38: 240068 | C38: 210486 | D38: 168945 | E38: 270289 | F38: 117345 | G38: 142212 | H38: 125050 | I38: 131051 | J38: 138651 | K38: 1544097

Sheet Charts_Data
A3: Revenue Comparison Across Cities by Service Type
A4: Sum of Revenue_INR | B4: Column Labels
A5: Row Labels | B5: Corporate | C5: Last-Mile | D5: Ride-Hailing | E5: Shuttle | F5: Grand Total
A6: Bangalore | B6: 898982 | C6: 772379 | D6: 530226 | E6: 923308 | F6: 3124895
A7: Chennai | B7: 851067 | C7: 755967 | D7: 559616 | E7: 514251 | F7: 2680901
A8: Delhi | B8: 391412 | C8: 745319 | D8: 852615 | E8: 814274 | F8: 2803620
A9: Hyderabad | B9: 613322 | C9: 936297 | D9: 939111 | E9: 475463 | F9: 2964193
A10: Mumbai | B10: 896268 | C10: 811063 | D10: 672525 | E10: 399369 | F10: 2779225
A11: Pune | B11: 825370 | C11: 420379 | D11: 688751 | E11: 679843 | F11: 2614343
A12: Grand Total | B12: 4476421 | C12: 4441404 | D12: 4242844 | E12: 3806508 | F12: 16967177
A15: Fleet Composition by Fuel Type
A16: Row Labels | B16: Count of Vehicle_ID
A17: CNG | B17: 5
A18: Diesel | B18: 9
A19: Electric | B19: 4
A20: Petrol | B20: 12
A21: Grand Total | B21: 30
A24: Monthly Revenue Trend by City
A25: Sum of Revenue_INR | B25: Column Labels
A26: Row Labels | B26: Bangalore | C26: Chennai | D26: Delhi | E26: Hyderabad | F26: Mumbai | G26: Pune | H26: Grand Total
A27: January | B27: 433604 | C27: 1057346 | D27: 538048 | E27: 457659 | F27: 471054 | G27: 807403 | H27: 3765114
A28: February | B28: 864165 | C28: 450498 | D28: 1024075 | E28: 542406 | F28: 942327 | G28: 562598 | H28: 4386069
A29: March | B29: 822597 | C29: 306400 | D29: 617248 | E29: 903625 | F29: 722160 | G29: 674868 | H29: 4046898
A30: April | B30: 1004529 | C30: 866657 | D30: 624249 | E30: 1060503 | F30: 643684 | G30: 569474 | H30: 4769096
A31: Grand Total | B31: 3124895 | C31: 2680901 | D31: 2803620 | E31: 2964193 | F31: 2779225 | G31: 2614343 | H31: 16967177
A35: Row Labels | B35: Sum of Revenue_INR | C35: Sum of Total_Trips
A36: Bangalore | B36: 3124895 | C36: 4495
A37: Chennai | B37: 2680901 | C37: 4141
A38: Delhi | B38: 2803620 | C38: 3910
A39: Hyderabad | B39: 2964193 | C39: 5346
A40: Mumbai | B40: 2779225 | C40: 4300
A41: Pune | B41: 2614343 | C41: 4199
A42: Grand Total | B42: 16967177 | C42: 26391

Sheet Dashboard_Charts

Sheet Fleet_Efficiency
A1: Vehicle_ID | B1: Revenue | C1: Distance (km) | D1: Revenue/km | E1: Maintenance Cost | F1: Cost Efficiency % | G1: Active Trips | H1: Total Possible Trips | I1: Driver Utilization % | J1: Rank
A2: VH001 | B2: =SUMIFS(Trip_Data!$K:$K,Trip_Data!$B:$B,A2) -> 4534.15 | C2: =SUMIFS(Trip_Data!$G:$G,Trip_Data!$B:$B,A2) -> 206.4 | D2: =IF(C2=0,0,B2/C2) -> 21.967781 | E2: =SUMIFS(Maintenance_Data!$F:$F,Maintenance_Data!$B:$B,A2) -> 42842 | F2: =IF(B2=0,0,E2/B2) -> 9.448739 | G2: =COUNTIF(Trip_Data!$B:$B,A2) -> 7 | H2: =121*8 -> 968 | I2: =G2/H2 -> 0.007231405 | J2: =RANK(D2,$D$2:$D$31,0) -> 10
A3: VH002 | B3: =SUMIFS(Trip_Data!$K:$K,Trip_Data!$B:$B,A3) -> 1310.56 | C3: =SUMIFS(Trip_Data!$G:$G,Trip_Data!$B:$B,A3) -> 62.1 | D3: =IF(C3=0,0,B3/C3) -> 21.104026 | E3: =SUMIFS(Maintenance_Data!$F:$F,Maintenance_Data!$B:$B,A3) -> 97104 | F3: =IF(B3=0,0,E3/B3) -> 74.093517 | G3: =COUNTIF(Trip_Data!$B:$B,A3) -> 2 | H3: =121*8 -> 968 | I3: =G3/H3 -> 0.0020661157 | J3: =RANK(D3,$D$2:$D$31,0) -> 11
A4: VH003 | B4: =SUMIFS(Trip_Data!$K:$K,Trip_Data!$B:$B,A4) -> 2192.05 | C4: =SUMIFS(Trip_Data!$G:$G,Trip_Data!$B:$B,A4) -> 110.6 | D4: =IF(C4=0,0,B4/C4) -> 19.81962 | E4: =SUMIFS(Maintenance_Data!$F:$F,Maintenance_Data!$B:$B,A4) -> 47455 | F4: =IF(B4=0,0,E4/B4) -> 21.648685 | G4: =COUNTIF(Trip_Data!$B:$B,A4) -> 5 | H4: =121*8 -> 968 | I4: =G4/H4 -> 0.0051652893 | J4: =RANK(D4,$D$2:$D$31,0) -> 14
A5: VH004 | B5: =SUMIFS(Trip_Data!$K:$K,Trip_Data!$B:$B,A5) -> 944.6 | C5: =SUMIFS(Trip_Data!$G:$G,Trip_Data!$B:$B,A5) -> 54.4 | D5: =IF(C5=0,0,B5/C5) -> 17.363971 | E5: =SUMIFS(Maintenance_Data!$F:$F,Maintenance_Data!$B:$B,A5) -> 49992 | F5: =IF(B5=0,0,E5/B5) -> 52.923989 | G5: =COUNTIF(Trip_Data!$B:$B,A5) -> 1 | H5: =121*8 -> 968 | I5: =G5/H5 -> 0.0010330579 | J5: =RANK(D5,$D$2:$D$31,0) -> 22
A6: VH005 | B6: =SUMIFS(Trip_Data!$K:$K,Trip_Data!$B:$B,A6) -> 2480.24 | C6: =SUMIFS(Trip_Data!$G:$G,Trip_Data!$B:$B,A6) -> 91.9 | D6: =IF(C6=0,0,B6/C6) -> 26.988466 | E6: =SUMIFS(Maintenance_Data!$F:$F,Maintenance_Data!$B:$B,A6) -> 40908 | F6: =IF(B6=0,0,E6/B6) -> 16.493565 | G6: =COUNTIF(Trip_Data!$B:$B,A6) -> 3 | H6: =121*8 -> 968 | I6: =G6/H6 -> 0.0030991736 | J6: =RANK(D6,$D$2:$D$31,0) -> 3
A7: VH006 | B7: =SUMIFS(Trip_Data!$K:$K,Trip_Data!$B:$B,A7) -> 0 | C7: =SUMIFS(Trip_Data!$G:$G,Trip_Data!$B:$B,A7) -> 0 | D7: =IF(C7=0,0,B7/C7) -> 0 | E7: =SUMIFS(Maintenance_Data!$F:$F,Maintenance_Data!$B:$B,A7) -> 29146 | F7: =IF(B7=0,0,E7/B7) -> 0 | G7: =COUNTIF(Trip_Data!$B:$B,A7) -> 0 | H7: =121*8 -> 968 | I7: =G7/H7 -> 0 | J7: =RANK(D7,$D$2:$D$31,0) -> 29
A8: VH007 | B8: =SUMIFS(Trip_Data!$K:$K,Trip_Data!$B:$B,A8) -> 1029.85 | C8: =SUMIFS(Trip_Data!$G:$G,Trip_Data!$B:$B,A8) -> 57.2 | D8: =IF(C8=0,0,B8/C8) -> 18.004371 | E8: =SUMIFS(Maintenance_Data!$F:$F,Maintenance_Data!$B:$B,A8) -> 71638 | F8: =IF(B8=0,0,E8/B8) -> 69.561587 | G8: =COUNTIF(Trip_Data!$B:$B,A8) -> 2 | H8: =121*8 -> 968 | I8: =G8/H8 -> 0.0020661157 | J8: =RANK(D8,$D$2:$D$31,0) -> 17
A9: VH008 | B9: =SUMIFS(Trip_Data!$K:$K,Trip_Data!$B:$B,A9) -> 2484.4 | C9: =SUMIFS(Trip_Data!$G:$G,Trip_Data!$B:$B,A9) -> 102.7 | D9: =IF(C9=0,0,B9/C9) -> 24.190847 | E9: =SUMIFS(Maintenance_Data!$F:$F,Maintenance_Data!$B:$B,A9) -> 5269 | F9: =IF(B9=0,0,E9/B9) -> 2.120834 | G9: =COUNTIF(Trip_Data!$B:$B,A9) -> 4 | H9: =121*8 -> 968 | I9: =G9/H9 -> 0.0041322314 | J9: =RANK(D9,$D$2:$D$31,0) -> 8
A10: VH009 | B10: =SUMIFS(Trip_Data!$K:$K,Trip_Data!$B:$B,A10) -> 4011.21 | C10: =SUMIFS(Trip_Data!$G:$G,Trip_Data!$B:$B,A10) -> 194 | D10: =IF(C10=0,0,B10/C10) -> 20.67634 | E10: =SUMIFS(Maintenance_Data!$F:$F,Maintenance_Data!$B:$B,A10) -> 30668 | F10: =IF(B10=0,0,E10/B10) -> 7.6455733 | G10: =COUNTIF(Trip_Data!$B:$B,A10) -> 5 | H10: =121*8 -> 968 | I10: =G10/H10 -> 0.0051652893 | J10: =RANK(D10,$D$2:$D$31,0) -> 13
A11: VH010 | B11: =SUMIFS(Trip_Data!$K:$K,Trip_Data!$B:$B,A11) -> 1649.08 | C11: =SUMIFS(Trip_Data!$G:$G,Trip_Data!$B:$B,A11) -> 101.9 | D11: =IF(C11=0,0,B11/C11) -> 16.183317 | E11: =SUMIFS(Maintenance_Data!$F:$F,Maintenance_Data!$B:$B,A11) -> 70846 | F11: =IF(B11=0,0,E11/B11) -> 42.960924 | G11: =COUNTIF(Trip_Data!$B:$B,A11) -> 2 | H11: =121*8 -> 968 | I11: =G11/H11 -> 0.0020661157 | J11: =RANK(D11,$D$2:$D$31,0) -> 24
A12: VH011 | B12: =SUMIFS(Trip_Data!$K:$K,Trip_Data!$B:$B,A12) -> 1263.52 | C12: =SUMIFS(Trip_Data!$G:$G,Trip_Data!$B:$B,A12) -> 60.3 | D12: =IF(C12=0,0,B12/C12) -> 20.953897 | E12: =SUMIFS(Maintenance_Data!$F:$F,Maintenance_Data!$B:$B,A12) -> 91371 | F12: =IF(B12=0,0,E12/B12) -> 72.314645 | G12: =COUNTIF(Trip_Data!$B:$B,A12) -> 3 | H12: =121*8 -> 968 | I12: =G12/H12 -> 0.0030991736 | J12: =RANK(D12,$D$2:$D$31,0) -> 12
A13: VH012 | B13: =SUMIFS(Trip_Data!$K:$K,Trip_Data!$B:$B,A13) -> 1842.71 | C13: =SUMIFS(Trip_Data!$G:$G,Trip_Data!$B:$B,A13) -> 71.1 | D13: =IF(C13=0,0,B13/C13) -> 25.917159 | E13: =SUMIFS(Maintenance_Data!$F:$F,Maintenance_Data!$B:$B,A13) -> 40947 | F13: =IF(B13=0,0,E13/B13) -> 22.221077 | G13: =COUNTIF(Trip_Data!$B:$B,A13) -> 3 | H13: =121*8 -> 968 | I13: =G13/H13 -> 0.0030991736 | J13: =RANK(D13,$D$2:$D$31,0) -> 5
... A31: VH030 | B31: =SUMIFS(Trip_Data!$K:$K,Trip_Data!$B:$B,A31) -> 1078.03 | C31: =SUMIFS(Trip_Data!$G:$G,Trip_Data!$B:$B,A31) -> 79.8 | D31: =IF(C31=0,0,B31/C31) -> 13.509148 | E31: =SUMIFS(Maintenance_Data!$F:$F,Maintenance_Data!$B:$B,A31) -> 91212 | F31: =IF(B31=0,0,E31/B31) -> 84.60989 | G31: =COUNTIF(Trip_Data!$B:$B,A31) -> 4 | H31: =121*8 -> 968 | I31: =G31/H31 -> 0.0041322314 | J31: =RANK(D31,$D$2:$D$31,0) -> 28

Sheet Scenario_Analysis
A1: Fuel Price Increase Analysis (10%,20%,30%) & Goal Seek | D1: Goal Seek
A2: Revenue | B2: 16967177 | D2: Revenue | E2: 16967177
A3: Fuel Cost | B3: 3910162 | D3: Fuel Cost | E3: 10678366
A4: Maintenance Cost | B4: 1664580 | D4: Maintenance Cost | E4: 1664580
A5: Driver Cost | B5: 4624231 | D5: Driver Cost | E5: 4624231
A6: Profit | B6: =B2-B3-B4-B5 -> 6768204 | D6: Profit | E6: =E2-E3-E4-E5 -> 0
A9: Fuel Increase | B9: New Fuel Cost | C9: New Profit
A10: 0.1 | B10: =$B$3*(1+A10) -> 4301178.2 | C10: =$B$2-B10-$B$4-$B$5 -> 6377187.8
A11: 0.2 | B11: =$B$3*(1+A11) -> 4692194.4 | C11: =$B$2-B11-$B$4-$B$5 -> 5986171.6
A12: 0.3 | B12: =$B$3*(1+A12) -> 5083210.6 | C12: =$B$2-B12-$B$4-$B$5 -> 5595155.4
A17: Surge Multiplier Analysis
A18: Surge Multiplier | B18: Estimated Revenue | C18: Estimated Profit
A19: 1 | B19: =$B$2*A19 -> 16967177 | C19: =B19-$B$3-$B$4-$B$5 -> 6768204
A20: 1.1 | B20: =$B$2*A20 -> 18663895 | C20: =B20-$B$3-$B$4-$B$5 -> 8464921.7
A21: 2.5 | B21: =$B$2*A21 -> 42417942 | C21: =B21-$B$3-$B$4-$B$5 -> 32218970
A24: Break-even Trips
A25: Vehicle | B25: Revenue | C25: Active Trips | D25: Maintenance | E25: Break-even Trips
A26: VH001 | B26: =Fleet_Efficiency!B2 -> 4534.15 | C26: =Fleet_Efficiency!G2 -> 7 | D26: =Fleet_Efficiency!E2 -> 42842 | E26: =IF(B26=0,0,D26*C26/B26) -> 66.141173
A27: VH002 | B27: =Fleet_Efficiency!B3 -> 1310.56 | C27: =Fleet_Efficiency!G3 -> 2 | D27: =Fleet_Efficiency!E3 -> 97104 | E27: =IF(B27=0,0,D27*C27/B27) -> 148.18703
A28: VH003 | B28: =Fleet_Efficiency!B4 -> 2192.05 | C28: =Fleet_Efficiency!G4 -> 5 | D28: =Fleet_Efficiency!E4 -> 47455 | E28: =IF(B28=0,0,D28*C28/B28) -> 108.24343
A29: VH004 | B29: =Fleet_Efficiency!B5 -> 944.6 | C29: =Fleet_Efficiency!G5 -> 1 | D29: =Fleet_Efficiency!E5 -> 49992 | E29: =IF(B29=0,0,D29*C29/B29) -> 52.923989
A30: VH005 | B30: =Fleet_Efficiency!B6 -> 2480.24 | C30: =Fleet_Efficiency!G6 -> 3 | D30: =Fleet_Efficiency!E6 -> 40908 | E30: =IF(B30=0,0,D30*C30/B30) -> 49.480695
A31: VH006 | B31: =Fleet_Efficiency!B7 -> 0 | C31: =Fleet_Efficiency!G7 -> 0 | D31: =Fleet_Efficiency!E7 -> 29146 | E31: =IF(B31=0,0,D31*C31/B31) -> 0
A32: VH007 | B32: =Fleet_Efficiency!B8 -> 1029.85 | C32: =Fleet_Efficiency!G8 -> 2 | D32: =Fleet_Efficiency!E8 -> 71638 | E32: =IF(B32=0,0,D32*C32/B32) -> 139.12317
A33: VH008 | B33: =Fleet_Efficiency!B9 -> 2484.4 | C33: =Fleet_Efficiency!G9 -> 4 | D33: =Fleet_Efficiency!E9 -> 5269 | E33: =IF(B33=0,0,D33*C33/B33) -> 8.483336
A34: VH009 | B34: =Fleet_Efficiency!B10 -> 4011.21 | C34: =Fleet_Efficiency!G10 -> 5 | D34: =Fleet_Efficiency!E10 -> 30668 | E34: =IF(B34=0,0,D34*C34/B34) -> 38.227866
A35: VH010 | B35: =Fleet_Efficiency!B11 -> 1649.08 | C35: =Fleet_Efficiency!G11 -> 2 | D35: =Fleet_Efficiency!E11 -> 70846 | E35: =IF(B35=0,0,D35*C35/B35) -> 85.921847
A36: VH011 | B36: =Fleet_Efficiency!B12 -> 1263.52 | C36: =Fleet_Efficiency!G12 -> 3 | D36: =Fleet_Efficiency!E12 -> 91371 | E36: =IF(B36=0,0,D36*C36/B36) -> 216.94393
A37: VH012 | B37: =Fleet_Efficiency!B13 -> 1842.71 | C37: =Fleet_Efficiency!G13 -> 3 | D37: =Fleet_Efficiency!E13 -> 40947 | E37: =IF(B37=0,0,D37*C37/B37) -> 66.66323
... A55: VH030 | B55: =Fleet_Efficiency!B31 -> 1078.03 | C55: =Fleet_Efficiency!G31 -> 4 | D55: =Fleet_Efficiency!E31 -> 91212 | E55: =IF(B55=0,0,D55*C55/B55) -> 338.43956

Sheet Executive_Summary
A1: WTi Cabs Fleet Performance Dashboard Executive Summary
N4: Total Fleet Size | O4: =COUNTA(Fleet_Vehicle_Data!A2:A31) -> 30
N5: Active Vehicles | O5: =COUNTIF(Fleet_Vehicle_Data!H2:H31,"Active") -> 25
N6: Total Revenue | O6: =SUM(Cleaned_Revenue!G2:G97) -> 16967177
N7: Average Driver Rating | O7: =AVERAGE(Fleet_Vehicle_Data!O2:O31) -> 4.2066667
A10: Month-over-Month Growth
B11: Feb vs Jan Revenue | C11: Mar vs Feb Revenue | D11: Apr vs Mar Revenue
A12: Revenue Growth | B12: 0.16492329 | C12: -0.077329153 | D12: 0.17845718 | K12: =(N13-N12)/N12 -> 0.16492329 | M12: January | N12: =SUMIF(Cleaned_Revenue!$A:$A,M12,Cleaned_Revenue!$G:$G) -> 3765114
K13: =(N14-N13)/N13 -> -0.077329153 | M13: February | N13: =SUMIF(Cleaned_Revenue!$A:$A,M13,Cleaned_Revenue!$G:$G) -> 4386069
A14: Top 5 Table | E14: Bottom 5 Table | K14: =(N15-N14)/N14 -> 0.17845718 | M14: March | N14: =SUMIF(Cleaned_Revenue!$A:$A,M14,Cleaned_Revenue!$G:$G) -> 4046898
A15: Rank | B15: Vehicle ID | C15: Revenue/km | E15: Rank | F15: Vehicle ID | G15: Revenue/km | M15: April | N15: =SUMIF(Cleaned_Revenue!$A:$A,M15,Cleaned_Revenue!$G:$G) -> 4769096
A16: 1 | B16: VH029 | C16: 31.83 | E16: 30 | F16: VH006 | G16: 0
A17: 2 | B17: VH016 | C17: 28.29 | E17: 29 | F17: VH027 | G17: 0
A18: 3 | B18: VH005 | C18: 26.99 | E18: 28 | F18: VH030 | G18: 13.51
A19: 4 | B19: VH028 | C19: 26.78 | E19: 27 | F19: VH022 | G19: 14.46
A20: 5 | B20: VH012 | C20: 25.92 | E20: 26 | F20: VH024 | G20: 14.97
