Workbook

Sheet All_India_Index_Upto_April23 (1
A1: Sector | B1: Year | C1: Month | D1: Cereals and products | E1: Meat and fish | F1: Egg | G1: Milk and products | H1: Oils and fats | I1: Fruits | J1: Vegetables | K1: Pulses and products | L1: Sugar and Confectionery | M1: Spices | N1: Non-alcoholic beverages | O1: Prepared meals, snacks, sweets etc. | P1: Food and beverages | Q1: Pan, tobacco and intoxicants | R1: Clothing | S1: Footwear | T1: Clothing and footwear | U1: Housing | V1: Fuel and light | W1: Household goods and services | X1: Health | Y1: Transport and communication | Z1: Recreation and amusement | AA1: Education | AB1: Personal care and effects | AC1: Miscellaneous | AD1: General index
A2: Rural | B2: 2013 | C2: January | D2: 107.5 | E2: 106.3 | F2: 108.1 | G2: 104.9 | H2: 106.1 | I2: 103.9 | J2: 101.9 | K2: 106.1 | L2: 106.8 | M2: 103.1 | N2: 104.8 | O2: 106.7 | P2: 105.5 | Q2: 105.1 | R2: 106.5 | S2: 105.8 | T2: 106.4 | U2: NA | V2: 105.5 | W2: 104.8 | X2: 104 | Y2: 103.3 | Z2: 103.4 | AA2: 103.8 | AB2: 104.7 | AC2: 104 | AD2: 105.1
A3: Urban | B3: 2013 | C3: January | D3: 110.5 | E3: 109.1 | F3: 113 | G3: 103.6 | H3: 103.4 | I3: 102.3 | J3: 102.9 | K3: 105.8 | L3: 105.1 | M3: 101.8 | N3: 105.1 | O3: 107.9 | P3: 105.9 | Q3: 105.2 | R3: 105.9 | S3: 105 | T3: 105.8 | U3: 100.3 | V3: 105.4 | W3: 104.8 | X3: 104.1 | Y3: 103.2 | Z3: 102.9 | AA3: 103.5 | AB3: 104.3 | AC3: 103.7 | AD3: 104
A4: Rural+Urban | B4: 2013 | C4: January | D4: 108.4 | E4: 107.3 | F4: 110 | G4: 104.4 | H4: 105.1 | I4: 103.2 | J4: 102.2 | K4: 106 | L4: 106.2 | M4: 102.7 | N4: 104.9 | O4: 107.3 | P4: 105.6 | Q4: 105.1 | R4: 106.3 | S4: 105.5 | T4: 106.2 | U4: 100.3 | V4: 105.5 | W4: 104.8 | X4: 104 | Y4: 103.2 | Z4: 103.1 | AA4: 103.6 | AB4: 104.5 | AC4: 103.9 | AD4: 104.6
A5: Rural | B5: 2013 | C5: February | D5: 109.2 | E5: 108.7 | F5: 110.2 | G5: 105.4 | H5: 106.7 | I5: 104 | J5: 102.4 | K5: 105.9 | L5: 105.7 | M5: 103.1 | N5: 105.1 | O5: 107.7 | P5: 106.3 | Q5: 105.6 | R5: 107.1 | S5: 106.3 | T5: 107 | U5: NA | V5: 106.2 | W5: 105.2 | X5: 104.4 | Y5: 103.9 | Z5: 104 | AA5: 104.1 | AB5: 104.6 | AC5: 104.4 | AD5: 105.8
A6: Urban | B6: 2013 | C6: February | D6: 112.9 | E6: 112.9 | F6: 116.9 | G6: 104 | H6: 103.5 | I6: 103.1 | J6: 104.9 | K6: 104.1 | L6: 103.8 | M6: 102.3 | N6: 106 | O6: 109 | P6: 107.2 | Q6: 106 | R6: 106.6 | S6: 105.5 | T6: 106.4 | U6: 100.4 | V6: 105.7 | W6: 105.2 | X6: 104.7 | Y6: 104.4 | Z6: 103.3 | AA6: 103.7 | AB6: 104.3 | AC6: 104.3 | AD6: 104.7
A7: Rural+Urban | B7: 2013 | C7: February | D7: 110.4 | E7: 110.2 | F7: 112.8 | G7: 104.9 | H7: 105.5 | I7: 103.6 | J7: 103.2 | K7: 105.3 | L7: 105.1 | M7: 102.8 | N7: 105.5 | O7: 108.3 | P7: 106.6 | Q7: 105.7 | R7: 106.9 | S7: 106 | T7: 106.8 | U7: 100.4 | V7: 106 | W7: 105.2 | X7: 104.5 | Y7: 104.2 | Z7: 103.6 | AA7: 103.9 | AB7: 104.5 | AC7: 104.4 | AD7: 105.3
A8: Rural | B8: 2013 | C8: March | D8: 110.2 | E8: 108.8 | F8: 109.9 | G8: 105.6 | H8: 106.2 | I8: 105.7 | J8: 101.4 | K8: 105.7 | L8: 105 | M8: 103.3 | N8: 105.6 | O8: 108.2 | P8: 106.6 | Q8: 106.5 | R8: 107.6 | S8: 106.8 | T8: 107.5 | U8: NA | V8: 106.1 | W8: 105.6 | X8: 104.7 | Y8: 104.6 | Z8: 104 | AA8: 104.3 | AB8: 104.3 | AC8: 104.6 | AD8: 106
A9: Urban | B9: 2013 | C9: March | D9: 113.9 | E9: 111.4 | F9: 113.2 | G9: 104.3 | H9: 102.7 | I9: 104.9 | J9: 103.8 | K9: 103.5 | L9: 102.6 | M9: 102.4 | N9: 107 | O9: 109.8 | P9: 107.3 | Q9: 106.8 | R9: 107.2 | S9: 106 | T9: 107 | U9: 100.4 | V9: 106 | W9: 105.7 | X9: 105.2 | Y9: 105.5 | Z9: 103.5 | AA9: 103.8 | AB9: 104.2 | AC9: 104.9 | AD9: 105
A10: Rural+Urban | B10: 2013 | C10: March | D10: 111.4 | E10: 109.7 | F10: 111.2 | G10: 105.1 | H10: 104.9 | I10: 105.3 | J10: 102.2 | K10: 105 | L10: 104.2 | M10: 103 | N10: 106.2 | O10: 108.9 | P10: 106.9 | Q10: 106.6 | R10: 107.4 | S10: 106.5 | T10: 107.3 | U10: 100.4 | V10: 106.1 | W10: 105.6 | X10: 104.9 | Y10: 105.1 | Z10: 103.7 | AA10: 104 | AB10: 104.3 | AC10: 104.7 | AD10: 105.5
A11: Rural | B11: 2013 | C11: April | D11: 110.2 | E11: 109.5 | F11: 106.9 | G11: 106.3 | H11: 105.7 | I11: 108.3 | J11: 103.4 | K11: 105.7 | L11: 104.2 | M11: 103.2 | N11: 106.5 | O11: 108.8 | P11: 107.1 | Q11: 107.1 | R11: 108.1 | S11: 107.4 | T11: 108 | U11: NA | V11: 106.5 | W11: 106.1 | X11: 105.1 | Y11: 104.4 | Z11: 104.5 | AA11: 104.8 | AB11: 102.7 | AC11: 104.6 | AD11: 106.4
A12: Urban | B12: 2013 | C12: April | D12: 114.6 | E12: 113.4 | F12: 106 | G12: 104.7 | H12: 102.1 | I12: 109.5 | J12: 109.7 | K12: 104.6 | L12: 102 | M12: 103.5 | N12: 108.2 | O12: 110.6 | P12: 108.8 | Q12: 108.5 | R12: 107.9 | S12: 106.4 | T12: 107.7 | U12: 100.5 | V12: 106.4 | W12: 106.5 | X12: 105.7 | Y12: 105 | Z12: 104 | AA12: 105.2 | AB12: 103.2 | AC12: 105.1 | AD12: 105.7
A13: Rural+Urban | B13: 2013 | C13: April | D13: 111.6 | E13: 110.9 | F13: 106.6 | G13: 105.7 | H13: 104.4 | I13: 108.9 | J13: 105.5 | K13: 105.3 | L13: 103.5 | M13: 103.3 | N13: 107.2 | O13: 109.6 | P13: 107.7 | Q13: 107.5 | R13: 108 | S13: 107 | T13: 107.9 | U13: 100.5 | V13: 106.5 | W13: 106.3 | X13: 105.3 | Y13: 104.7 | Z13: 104.2 | AA13: 105 | AB13: 102.9 | AC13: 104.8 | AD13: 106.1
A14: Rural | B14: 2013 | C14: May | D14: 110.9 | E14: 109.8 | F14: 105.9 | G14: 107.5 | H14: 105.3 | I14: 108.1 | J14: 107.3 | K14: 106.1 | L14: 103.7 | M14: 104 | N14: 107.4 | O14: 109.9 | P14: 108.1 | Q14: 108.1 | R14: 108.8 | S14: 107.9 | T14: 108.6 | U14: NA | V14: 107.5 | W14: 106.8 | X14: 105.7 | Y14: 104.1 | Z14: 105 | AA14: 105.5 | AB14: 102.1 | AC14: 104.8 | AD14: 107.2
A15: Urban | B15: 2013 | C15: May | D15: 115.4 | E15: 114.2 | F15: 102.7 | G15: 105.5 | H15: 101.5 | I15: 110.6 | J15: 123.7 | K15: 105.2 | L15: 101.9 | M15: 105 | N15: 109.1 | O15: 111.3 | P15: 111.1 | Q15: 109.8 | R15: 108.5 | S15: 106.7 | T15: 108.3 | U15: 100.5 | V15: 107.2 | W15: 107.1 | X15: 106.2 | Y15: 103.9 | Z15: 104.6 | AA15: 105.7 | AB15: 102.6 | AC15: 104.9 | AD15: 106.6
A16: Rural+Urban | B16: 2013 | C16: May | D16: 112.3 | E16: 111.3 | F16: 104.7 | G16: 106.8 | H16: 103.9 | I16: 109.3 | J16: 112.9 | K16: 105.8 | L16: 103.1 | M16: 104.3 | N16: 108.1 | O16: 110.5 | P16: 109.2 | Q16: 108.6 | R16: 108.7 | S16: 107.4 | T16: 108.5 | U16: 100.5 | V16: 107.4 | W16: 106.9 | X16: 105.9 | Y16: 104 | Z16: 104.8 | AA16: 105.6 | AB16: 102.3 | AC16: 104.8 | AD16: 106.9
A17: Rural | B17: 2013 | C17: June | D17: 112.3 | E17: 112.1 | F17: 108.1 | G17: 108.3 | H17: 105.9 | I17: 109.2 | J17: 118 | K17: 106.8 | L17: 104.1 | M17: 105.4 | N17: 108.2 | O17: 111 | P17: 110.6 | Q17: 109 | R17: 109.7 | S17: 108.8 | T17: 109.5 | U17: NA | V17: 108.5 | W17: 107.5 | X17: 106.3 | Y17: 105 | Z17: 105.6 | AA17: 106.5 | AB17: 102.5 | AC17: 105.5 | AD17: 108.9
A18: Urban | B18: 2013 | C18: June | D18: 117 | E18: 120.1 | F18: 112.5 | G18: 107.3 | H18: 101.3 | I18: 112.4 | J18: 143.6 | K18: 105.4 | L18: 101.4 | M18: 106.4 | N18: 110 | O18: 112.2 | P18: 115 | Q18: 110.9 | R18: 109.2 | S18: 107.2 | T18: 108.9 | U18: 106.6 | V18: 108 | W18: 107.7 | X18: 106.5 | Y18: 105.2 | Z18: 105.2 | AA18: 108.1 | AB18: 103.3 | AC18: 106.1 | AD18: 109.7
A19: Rural+Urban | B19: 2013 | C19: June | D19: 113.8 | E19: 114.9 | F19: 109.8 | G19: 107.9 | H19: 104.2 | I19: 110.7 | J19: 126.7 | K19: 106.3 | L19: 103.2 | M19: 105.7 | N19: 109 | O19: 111.6 | P19: 112.2 | Q19: 109.5 | R19: 109.5 | S19: 108.1 | T19: 109.3 | U19: 106.6 | V19: 108.3 | W19: 107.6 | X19: 106.4 | Y19: 105.1 | Z19: 105.4 | AA19: 107.4 | AB19: 102.8 | AC19: 105.8 | AD19: 109.3
A20: Rural | B20: 2013 | C20: July | D20: 113.4 | E20: 114.9 | F20: 110.5 | G20: 109.3 | H20: 106.2 | I20: 110.3 | J20: 129.2 | K20: 107.1 | L20: 104.3 | M20: 106.4 | N20: 109.1 | O20: 112.1 | P20: 113.1 | Q20: 109.8 | R20: 110.5 | S20: 109.5 | T20: 110.3 | U20: NA | V20: 109.5 | W20: 108.3 | X20: 106.9 | Y20: 106.8 | Z20: 106.4 | AA20: 107.8 | AB20: 102.5 | AC20: 106.5 | AD20: 110.7
A21: Urban | B21: 2013 | C21: July | D21: 117.8 | E21: 119.2 | F21: 114 | G21: 108.3 | H21: 101.1 | I21: 113.2 | J21: 160.9 | K21: 105.1 | L21: 101.3 | M21: 107.5 | N21: 110.4 | O21: 113.1 | P21: 117.5 | Q21: 111.7 | R21: 109.8 | S21: 107.8 | T21: 109.5 | U21: 107.7 | V21: 108.6 | W21: 108.1 | X21: 107.1 | Y21: 107.3 | Z21: 105.9 | AA21: 110.1 | AB21: 103.2 | AC21: 107.3 | AD21: 111.4
A22: Rural+Urban | B22: 2013 | C22: July | D22: 114.8 | E22: 116.4 | F22: 111.9 | G22: 108.9 | H22: 104.3 | I22: 111.7 | J22: 140 | K22: 106.4 | L22: 103.3 | M22: 106.8 | N22: 109.6 | O22: 112.6 | P22: 114.7 | Q22: 110.3 | R22: 110.2 | S22: 108.8 | T22: 110 | U22: 107.7 | V22: 109.2 | W22: 108.2 | X22: 107 | Y22: 107.1 | Z22: 106.1 | AA22: 109.1 | AB22: 102.8 | AC22: 106.9 | AD22: 111
A23: Rural | B23: 2013 | C23: August | D23: 114.3 | E23: 115.4 | F23: 111.1 | G23: 110 | H23: 106.4 | I23: 110.8 | J23: 138.9 | K23: 107.4 | L23: 104.1 | M23: 106.9 | N23: 109.7 | O23: 112.6 | P23: 114.9 | Q23: 110.7 | R23: 111.3 | S23: 110.2 | T23: 111.1 | U23: NA | V23: 109.9 | W23: 108.7 | X23: 107.5 | Y23: 107.8 | Z23: 106.8 | AA23: 108.7 | AB23: 105 | AC23: 107.5 | AD23: 112.1
A24: Urban | B24: 2013 | C24: August | D24: 118.3 | E24: 120.4 | F24: 112.7 | G24: 108.9 | H24: 101.1 | I24: 108.7 | J24: 177 | K24: 104.7 | L24: 101 | M24: 108.5 | N24: 110.9 | O24: 114.3 | P24: 119.6 | Q24: 112.4 | R24: 110.6 | S24: 108.3 | T24: 110.2 | U24: 108.9 | V24: 109.3 | W24: 108.7 | X24: 107.6 | Y24: 108.1 | Z24: 106.5 | AA24: 110.8 | AB24: 106 | AC24: 108.3 | AD24: 112.7
A25: Rural+Urban | B25: 2013 | C25: August | D25: 115.6 | E25: 117.2 | F25: 111.7 | G25: 109.6 | H25: 104.5 | I25: 109.8 | J25: 151.8 | K25: 106.5 | L25: 103.1 | M25: 107.4 | N25: 110.2 | O25: 113.4 | P25: 116.6 | Q25: 111.2 | R25: 111 | S25: 109.4 | T25: 110.7 | U25: 108.9 | V25: 109.7 | W25: 108.7 | X25: 107.5 | Y25: 108 | Z25: 106.6 | AA25: 109.9 | AB25: 105.4 | AC25: 107.9 | AD25: 112.4
A26: Rural | B26: 2013 | C26: September | D26: 115.4 | E26: 115.7 | F26: 111.7 | G26: 111 | H26: 107.4 | I26: 110.9 | J26: 154 | K26: 108.1 | L26: 104.2 | M26: 107.9 | N26: 110.4 | O26: 114 | P26: 117.8 | Q26: 111.7 | R26: 112.7 | S26: 111.4 | T26: 112.5 | U26: NA | V26: 111.1 | W26: 109.6 | X26: 108.3 | Y26: 109.3 | Z26: 107.7 | AA26: 109.8 | AB26: 106.7 | AC26: 108.7 | AD26: 114.2
A27: Urban | B27: 2013 | C27: September | D27: 118.6 | E27: 119.1 | F27: 113.2 | G27: 109.6 | H27: 101.7 | I27: 103.2 | J27: 174.3 | K27: 105.1 | L27: 100.8 | M27: 109.1 | N27: 111.1 | O27: 115.4 | P27: 119.2 | Q27: 112.9 | R27: 111.4 | S27: 109 | T27: 111.1 | U27: 109.7 | V27: 109.5 | W27: 109.6 | X27: 107.9 | Y27: 110.4 | Z27: 107.4 | AA27: 111.2 | AB27: 106.9 | AC27: 109.4 | AD27: 113.2
A28: Rural+Urban | B28: 2013 | C28: September | D28: 116.4 | E28: 116.9 | F28: 112.3 | G28: 110.5 | H28: 105.3 | I28: 107.3 | J28: 160.9 | K28: 107.1 | L28: 103.1 | M28: 108.3 | N28: 110.7 | O28: 114.6 | P28: 118.3 | Q28: 112 | R28: 112.2 | S28: 110.4 | T28: 111.9 | U28: 109.7 | V28: 110.5 | W28: 109.6 | X28: 108.1 | Y28: 109.9 | Z28: 107.5 | AA28: 110.6 | AB28: 106.8 | AC28: 109 | AD28: 113.7
A29: Rural | B29: 2013 | C29: October | D29: 116.3 | E29: 115.4 | F29: 112.6 | G29: 111.7 | H29: 107.7 | I29: 113.2 | J29: 164.9 | K29: 108.3 | L29: 103.9 | M29: 108.2 | N29: 111.1 | O29: 114.9 | P29: 119.8 | Q29: 112.2 | R29: 113.6 | S29: 112.3 | T29: 113.4 | U29: NA | V29: 111.6 | W29: 110.4 | X29: 108.9 | Y29: 109.3 | Z29: 108.3 | AA29: 110.2 | AB29: 107.5 | AC29: 109.1 | AD29: 115.5
A30: Urban | B30: 2013 | C30: October | D30: 118.9 | E30: 118.1 | F30: 114.5 | G30: 110.4 | H30: 102.3 | I30: 106.2 | J30: 183.5 | K30: 105.3 | L30: 100.2 | M30: 109.6 | N30: 111.4 | O30: 116 | P30: 120.8 | Q30: 113.5 | R30: 112.5 | S30: 109.7 | T30: 112 | U30: 110.5 | V30: 109.7 | W30: 110.2 | X30: 108.2 | Y30: 109.7 | Z30: 108 | AA30: 111.3 | AB30: 107.3 | AC30: 109.4 | AD30: 114
A31: Rural+Urban | B31: 2013 | C31: October | D31: 117.1 | E31: 116.3 | F31: 113.3 | G31: 111.2 | H31: 105.7 | I31: 109.9 | J31: 171.2 | K31: 107.3 | L31: 102.7 | M31: 108.7 | N31: 111.2 | O31: 115.4 | P31: 120.2 | Q31: 112.5 | R31: 113.2 | S31: 111.2 | T31: 112.8 | U31: 110.5 | V31: 110.9 | W31: 110.3 | X31: 108.6 | Y31: 109.5 | Z31: 108.1 | AA31: 110.8 | AB31: 107.4 | AC31: 109.2 | AD31: 114.8
A32: Rural | B32: 2013 | C32: November | D32: 117.3 | E32: 114.9 | F32: 116.2 | G32: 112.8 | H32: 108.9 | I32: 116.6 | J32: 178.1 | K32: 109.1 | L32: 103.6 | M32: 109 | N32: 111.8 | O32: 116 | P32: 122.5 | Q32: 112.8 | R32: 114.6 | S32: 113.1 | T32: 114.4 | U32: NA | V32: 112.6 | W32: 111.3 | X32: 109.7 | Y32: 109.6 | Z32: 108.7 | AA32: 111 | AB32: 108.2 | AC32: 109.8 | AD32: 117.4
A33: Urban | B33: 2013 | C33: November | D33: 119.8 | E33: 116.3 | F33: 122.6 | G33: 112 | H33: 103.2 | I33: 110 | J33: 192.8 | K33: 106.3 | L33: 99.5 | M33: 110.3 | N33: 111.8 | O33: 117.1 | P33: 122.9 | Q33: 114.1 | R33: 113.5 | S33: 110.3 | T33: 113 | U33: 111.1 | V33: 110 | W33: 110.9 | X33: 108.6 | Y33: 109.5 | Z33: 108.5 | AA33: 111.3 | AB33: 107.9 | AC33: 109.6 | AD33: 115
A34: Rural+Urban | B34: 2013 | C34: November | D34: 118.1 | E34: 115.4 | F34: 118.7 | G34: 112.5 | H34: 106.8 | I34: 113.5 | J34: 183.1 | K34: 108.2 | L34: 102.2 | M34: 109.4 | N34: 111.8 | O34: 116.5 | P34: 122.6 | Q34: 113.1 | R34: 114.2 | S34: 111.9 | T34: 113.8 | U34: 111.1 | V34: 111.6 | W34: 111.1 | X34: 109.3 | Y34: 109.5 | Z34: 108.6 | AA34: 111.2 | AB34: 108.1 | AC34: 109.7 | AD34: 116.3
A35: Rural | B35: 2013 | C35: December | D35: 118.4 | E35: 115.9 | F35: 120.4 | G35: 113.8 | H35: 109.5 | I35: 115.5 | J35: 145.7 | K35: 109.5 | L35: 102.9 | M35: 109.8 | N35: 112.1 | O35: 116.8 | P35: 118.7 | Q35: 113.6 | R35: 115.8 | S35: 114 | T35: 115.5 | U35: NA | V35: 112.8 | W35: 112.1 | X35: 110.1 | Y35: 109.9 | Z35: 109.2 | AA35: 111.6 | AB35: 108.1 | AC35: 110.1 | AD35: 115.5
A36: Urban | B36: 2013 | C36: December | D36: 120.5 | E36: 118.1 | F36: 128.5 | G36: 112.8 | H36: 103.4 | I36: 110.7 | J36: 144.8 | K36: 107.1 | L36: 98.6 | M36: 111.9 | N36: 112.1 | O36: 118.1 | P36: 117.8 | Q36: 115 | R36: 114.2 | S36: 110.9 | T36: 113.7 | U36: 110.7 | V36: 110.4 | W36: 111.3 | X36: 109 | Y36: 109.7 | Z36: 108.9 | AA36: 111.4 | AB36: 107.7 | AC36: 109.8 | AD36: 113.3
A37: Rural+Urban | B37: 2013 | C37: December | D37: 119.1 | E37: 116.7 | F37: 123.5 | G37: 113.4 | H37: 107.3 | I37: 113.3 | J37: 145.4 | K37: 108.7 | L37: 101.5 | M37: 110.5 | N37: 112.1 | O37: 117.4 | P37: 118.4 | Q37: 114 | R37: 115.2 | S37: 112.7 | T37: 114.8 | U37: 110.7 | V37: 111.9 | W37: 111.7 | X37: 109.7 | Y37: 109.8 | Z37: 109 | AA37: 111.5 | AB37: 107.9 | AC37: 110 | AD37: 114.5
A38: Rural | B38: 2014 | C38: January | D38: 118.9 | E38: 117.1 | F38: 120.5 | G38: 114.4 | H38: 109 | I38: 115.5 | J38: 123.9 | K38: 109.6 | L38: 101.8 | M38: 110.2 | N38: 112.4 | O38: 117.3 | P38: 116 | Q38: 114 | R38: 116.5 | S38: 114.5 | T38: 116.2 | U38: NA | V38: 113 | W38: 112.6 | X38: 110.6 | Y38: 110.5 | Z38: 109.6 | AA38: 111.8 | AB38: 108.3 | AC38: 110.6 | AD38: 114.2
A39: Urban | B39: 2014 | C39: January | D39: 121.2 | E39: 122 | F39: 129.9 | G39: 113.6 | H39: 102.9 | I39: 112.1 | J39: 118.9 | K39: 107.5 | L39: 96.9 | M39: 112.7 | N39: 112.1 | O39: 119 | P39: 115.5 | Q39: 115.7 | R39: 114.8 | S39: 111.3 | T39: 114.3 | U39: 111.6 | V39: 111 | W39: 111.9 | X39: 109.7 | Y39: 110.8 | Z39: 109.8 | AA39: 111.5 | AB39: 108 | AC39: 110.5 | AD39: 112.9
A40: Rural+Urban | B40: 2014 | C40: January | D40: 119.6 | E40: 118.8 | F40: 124.1 | G40: 114.1 | H40: 106.8 | I40: 113.9 | J40: 122.2 | K40: 108.9 | L40: 100.2 | M40: 111 | N40: 112.3 | O40: 118.1 | P40: 115.8 | Q40: 114.5 | R40: 115.8 | S40: 113.2 | T40: 115.4 | U40: 111.6 | V40: 112.2 | W40: 112.3 | X40: 110.3 | Y40: 110.7 | Z40: 109.7 | AA40: 111.6 | AB40: 108.2 | AC40: 110.6 | AD40: 113.6
...

Sheet Data Clean
A1: Sector | B1: Year | C1: Month | D1: Cereals and products | E1: Meat and fish | F1: Egg | G1: Milk and products | H1: Oils and fats | I1: Fruits | J1: Vegetables | K1: Pulses and products | L1: Sugar and Confectionery | M1: Spices | N1: Non-alcoholic beverages | O1: Prepared meals, snacks, sweets etc. | P1: Food and beverages | Q1: Pan, tobacco and intoxicants | R1: Clothing | S1: Footwear | T1: Clothing and footwear | U1: Housing | V1: Fuel and light | W1: Household goods and services | X1: Health | Y1: Transport and communication | Z1: Recreation and amusement | AA1: Education | AB1: Personal care and effects | AC1: Miscellaneous | AD1: General index
A2: Rural | B2: 2013 | C2: January | D2: 107.5 | E2: 106.3 | F2: 108.1 | G2: 104.9 | H2: 106.1 | I2: 103.9 | J2: 101.9 | K2: 106.1 | L2: 106.8 | M2: 103.1 | N2: 104.8 | O2: 106.7 | P2: 105.5 | Q2: 105.1 | R2: 106.5 | S2: 105.8 | T2: 106.4 | U2: 100.3 | V2: 105.5 | W2: 104.8 | X2: 104 | Y2: 103.3 | Z2: 103.4 | AA2: 103.8 | AB2: 104.7 | AC2: 104 | AD2: 105.1
A3: Urban | B3: 2013 | C3: January | D3: 110.5 | E3: 109.1 | F3: 113 | G3: 103.6 | H3: 103.4 | I3: 102.3 | J3: 102.9 | K3: 105.8 | L3: 105.1 | M3: 101.8 | N3: 105.1 | O3: 107.9 | P3: 105.9 | Q3: 105.2 | R3: 105.9 | S3: 105 | T3: 105.8 | U3: 100.3 | V3: 105.4 | W3: 104.8 | X3: 104.1 | Y3: 103.2 | Z3: 102.9 | AA3: 103.5 | AB3: 104.3 | AC3: 103.7 | AD3: 104
A4: Rural+Urban | B4: 2013 | C4: January | D4: 108.4 | E4: 107.3 | F4: 110 | G4: 104.4 | H4: 105.1 | I4: 103.2 | J4: 102.2 | K4: 106 | L4: 106.2 | M4: 102.7 | N4: 104.9 | O4: 107.3 | P4: 105.6 | Q4: 105.1 | R4: 106.3 | S4: 105.5 | T4: 106.2 | U4: 100.3 | V4: 105.5 | W4: 104.8 | X4: 104 | Y4: 103.2 | Z4: 103.1 | AA4: 103.6 | AB4: 104.5 | AC4: 103.9 | AD4: 104.6
A5: Rural | B5: 2013 | C5: February | D5: 109.2 | E5: 108.7 | F5: 110.2 | G5: 105.4 | H5: 106.7 | I5: 104 | J5: 102.4 | K5: 105.9 | L5: 105.7 | M5: 103.1 | N5: 105.1 | O5: 107.7 | P5: 106.3 | Q5: 105.6 | R5: 107.1 | S5: 106.3 | T5: 107 | U5: 100.4 | V5: 106.2 | W5: 105.2 | X5: 104.4 | Y5: 103.9 | Z5: 104 | AA5: 104.1 | AB5: 104.6 | AC5: 104.4 | AD5: 105.8
A6: Urban | B6: 2013 | C6: February | D6: 112.9 | E6: 112.9 | F6: 116.9 | G6: 104 | H6: 103.5 | I6: 103.1 | J6: 104.9 | K6: 104.1 | L6: 103.8 | M6: 102.3 | N6: 106 | O6: 109 | P6: 107.2 | Q6: 106 | R6: 106.6 | S6: 105.5 | T6: 106.4 | U6: 100.4 | V6: 105.7 | W6: 105.2 | X6: 104.7 | Y6: 104.4 | Z6: 103.3 | AA6: 103.7 | AB6: 104.3 | AC6: 104.3 | AD6: 104.7
A7: Rural+Urban | B7: 2013 | C7: February | D7: 110.4 | E7: 110.2 | F7: 112.8 | G7: 104.9 | H7: 105.5 | I7: 103.6 | J7: 103.2 | K7: 105.3 | L7: 105.1 | M7: 102.8 | N7: 105.5 | O7: 108.3 | P7: 106.6 | Q7: 105.7 | R7: 106.9 | S7: 106 | T7: 106.8 | U7: 100.4 | V7: 106 | W7: 105.2 | X7: 104.5 | Y7: 104.2 | Z7: 103.6 | AA7: 103.9 | AB7: 104.5 | AC7: 104.4 | AD7: 105.3
A8: Rural | B8: 2013 | C8: March | D8: 110.2 | E8: 108.8 | F8: 109.9 | G8: 105.6 | H8: 106.2 | I8: 105.7 | J8: 101.4 | K8: 105.7 | L8: 105 | M8: 103.3 | N8: 105.6 | O8: 108.2 | P8: 106.6 | Q8: 106.5 | R8: 107.6 | S8: 106.8 | T8: 107.5 | U8: 100.4 | V8: 106.1 | W8: 105.6 | X8: 104.7 | Y8: 104.6 | Z8: 104 | AA8: 104.3 | AB8: 104.3 | AC8: 104.6 | AD8: 106
A9: Urban | B9: 2013 | C9: March | D9: 113.9 | E9: 111.4 | F9: 113.2 | G9: 104.3 | H9: 102.7 | I9: 104.9 | J9: 103.8 | K9: 103.5 | L9: 102.6 | M9: 102.4 | N9: 107 | O9: 109.8 | P9: 107.3 | Q9: 106.8 | R9: 107.2 | S9: 106 | T9: 107 | U9: 100.4 | V9: 106 | W9: 105.7 | X9: 105.2 | Y9: 105.5 | Z9: 103.5 | AA9: 103.8 | AB9: 104.2 | AC9: 104.9 | AD9: 105
A10: Rural+Urban | B10: 2013 | C10: March | D10: 111.4 | E10: 109.7 | F10: 111.2 | G10: 105.1 | H10: 104.9 | I10: 105.3 | J10: 102.2 | K10: 105 | L10: 104.2 | M10: 103 | N10: 106.2 | O10: 108.9 | P10: 106.9 | Q10: 106.6 | R10: 107.4 | S10: 106.5 | T10: 107.3 | U10: 100.4 | V10: 106.1 | W10: 105.6 | X10: 104.9 | Y10: 105.1 | Z10: 103.7 | AA10: 104 | AB10: 104.3 | AC10: 104.7 | AD10: 105.5
A11: Rural | B11: 2013 | C11: April | D11: 110.2 | E11: 109.5 | F11: 106.9 | G11: 106.3 | H11: 105.7 | I11: 108.3 | J11: 103.4 | K11: 105.7 | L11: 104.2 | M11: 103.2 | N11: 106.5 | O11: 108.8 | P11: 107.1 | Q11: 107.1 | R11: 108.1 | S11: 107.4 | T11: 108 | U11: 100.5 | V11: 106.5 | W11: 106.1 | X11: 105.1 | Y11: 104.4 | Z11: 104.5 | AA11: 104.8 | AB11: 102.7 | AC11: 104.6 | AD11: 106.4
A12: Urban | B12: 2013 | C12: April | D12: 114.6 | E12: 113.4 | F12: 106 | G12: 104.7 | H12: 102.1 | I12: 109.5 | J12: 109.7 | K12: 104.6 | L12: 102 | M12: 103.5 | N12: 108.2 | O12: 110.6 | P12: 108.8 | Q12: 108.5 | R12: 107.9 | S12: 106.4 | T12: 107.7 | U12: 100.5 | V12: 106.4 | W12: 106.5 | X12: 105.7 | Y12: 105 | Z12: 104 | AA12: 105.2 | AB12: 103.2 | AC12: 105.1 | AD12: 105.7
A13: Rural+Urban | B13: 2013 | C13: April | D13: 111.6 | E13: 110.9 | F13: 106.6 | G13: 105.7 | H13: 104.4 | I13: 108.9 | J13: 105.5 | K13: 105.3 | L13: 103.5 | M13: 103.3 | N13: 107.2 | O13: 109.6 | P13: 107.7 | Q13: 107.5 | R13: 108 | S13: 107 | T13: 107.9 | U13: 100.5 | V13: 106.5 | W13: 106.3 | X13: 105.3 | Y13: 104.7 | Z13: 104.2 | AA13: 105 | AB13: 102.9 | AC13: 104.8 | AD13: 106.1
... A373: Rural+Urban | B373: 2023 | C373: May | D373: 173.7 | E373: 214.3 | F373: 173.2 | G373: 179.5 | H373: 170 | I373: 172.2 | J373: 161 | K373: 175.6 | L373: 122.7 | M373: 218 | N373: 173.4 | O373: 194.2 | P373: 179.1 | Q373: 201 | R373: 187.3 | S373: 179.7 | T373: 186.2 | U373: 175.6 | V373: 182.8 | W373: 175.2 | X373: 185.7 | Y373: 164.8 | Z373: 171.2 | AA373: 177.1 | AB373: 185.2 | AC373: 175.7 | AD373: 179.1

Sheet Problem 1
A1: Sector | B1: Year | C1: Month | D1: Cereals and products | E1: Meat and fish | F1: Egg | G1: Milk and products | H1: Oils and fats | I1: Fruits | J1: Vegetables | K1: Pulses and products | L1: Sugar and Confectionery | M1: Spices | N1: Non-alcoholic beverages | O1: Prepared meals, snacks, sweets etc. | P1: Food and beverages | Q1: Pan, tobacco and intoxicants | R1: Clothing | S1: Footwear | T1: Clothing and footwear | U1: Housing | V1: Fuel and light | W1: Household goods and services | X1: Health | Y1: Transport and communication | Z1: Recreation and amusement | AA1: Education | AB1: Personal care and effects | AC1: Miscellaneous | AD1: General index
A2: Rural+Urban | B2: 2023 | C2: May | D2: 173.7 | E2: 214.3 | F2: 173.2 | G2: 179.5 | H2: 170 | I2: 172.2 | J2: 161 | K2: 175.6 | L2: 122.7 | M2: 218 | N2: 173.4 | O2: 194.2 | P2: 179.1 | Q2: 201 | R2: 187.3 | S2: 179.7 | T2: 186.2 | U2: 175.6 | V2: 182.8 | W2: 175.2 | X2: 185.7 | Y2: 164.8 | Z2: 171.2 | AA2: 177.1 | AB2: 185.2 | AC2: 175.7 | AD2: 179.1
A4: Broader Category | B4: Calculated Value (Approx) | C4: Contribution %
A5: Food | B5: =SUM(D2:O2) -> 2127.8 | C5: =(B5/$B$16)*100 -> 51.728497
A6: Stimulants | B6: =Q2 -> 201 | C6: =(B6/$B$16)*100 -> 4.8864686
A7: Clothing | B7: =SUM(R2:S2) -> 367 | C7: =(B7/$B$16)*100 -> 8.9220596
A8: Housing | B8: =U2 -> 175.6 | C8: =(B8/$B$16)*100 -> 4.2689746
A9: Energy | B9: =V2 -> 182.8 | C9: =(B9/$B$16)*100 -> 4.4440123
A10: Household | B10: =W2 -> 175.2 | C10: =(B10/$B$16)*100 -> 4.2592503
A11: Health | B11: =X2 -> 185.7 | C11: =(B11/$B$16)*100 -> 4.5145135
A12: Transportation | B12: =Y2 -> 164.8 | C12: =(B12/$B$16)*100 -> 4.006418
A13: Recreation | B13: =Z2 -> 171.2 | C13: =(B13/$B$16)*100 -> 4.1620071
A14: Education | B14: =AA2 -> 177.1 | C14: =(B14/$B$16)*100 -> 4.3054408
A15: Personal Care | B15: =AB2 -> 185.2 | C15: =(B15/$B$16)*100 -> 4.5023581
A16: Total | B16: =SUM(B5:B15) -> 4113.4 | C16: 100

Sheet Problem 2
A1: Year | B1: Jan index | C1: Dec index | D1: Inflation %
A2: 2017 | B2: =SUMIFS('Data Clean'!AD:AD,'Data Clean'!A:A,"Rural+Urban",'Data Clean'!B:B,A2,'Data Clean'!C:C,"January") -> 130.3 | C2: =SUMIFS('Data Clean'!AD:AD,'Data Clean'!A:A,"Rural+Urban",'Data Clean'!B:B,A2,'Data Clean'!C:C,"December") -> 137.2 | D2: =((C2-B2)/B2)*100 -> 5.295472
A3: 2018 | B3: =SUMIFS('Data Clean'!AD:AD,'Data Clean'!A:A,"Rural+Urban",'Data Clean'!B:B,A3,'Data Clean'!C:C,"January") -> 136.9 | C3: =SUMIFS('Data Clean'!AD:AD,'Data Clean'!A:A,"Rural+Urban",'Data Clean'!B:B,A3,'Data Clean'!C:C,"December") -> 140.1 | D3: =((C3-B3)/B3)*100 -> 2.3374726
A4: 2019 | B4: =SUMIFS('Data Clean'!AD:AD,'Data Clean'!A:A,"Rural+Urban",'Data Clean'!B:B,A4,'Data Clean'!C:C,"January") -> 139.6 | C4: =SUMIFS('Data Clean'!AD:AD,'Data Clean'!A:A,"Rural+Urban",'Data Clean'!B:B,A4,'Data Clean'!C:C,"December") -> 150.4 | D4: =((C4-B4)/B4)*100 -> 7.7363897
A5: 2020 | B5: =SUMIFS('Data Clean'!AD:AD,'Data Clean'!A:A,"Rural+Urban",'Data Clean'!B:B,A5,'Data Clean'!C:C,"January") -> 150.2 | C5: =SUMIFS('Data Clean'!AD:AD,'Data Clean'!A:A,"Rural+Urban",'Data Clean'!B:B,A5,'Data Clean'!C:C,"December") -> 158.9 | D5: =((C5-B5)/B5)*100 -> 5.792277
A6: 2021 | B6: =SUMIFS('Data Clean'!AD:AD,'Data Clean'!A:A,"Rural+Urban",'Data Clean'!B:B,A6,'Data Clean'!C:C,"January") -> 157.3 | C6: =SUMIFS('Data Clean'!AD:AD,'Data Clean'!A:A,"Rural+Urban",'Data Clean'!B:B,A6,'Data Clean'!C:C,"December") -> 166.2 | D6: =((C6-B6)/B6)*100 -> 5.6579784
A7: 2022 | B7: =SUMIFS('Data Clean'!AD:AD,'Data Clean'!A:A,"Rural+Urban",'Data Clean'!B:B,A7,'Data Clean'!C:C,"January") -> 165.7 | C7: =SUMIFS('Data Clean'!AD:AD,'Data Clean'!A:A,"Rural+Urban",'Data Clean'!B:B,A7,'Data Clean'!C:C,"December") -> 175.7 | D7: =((C7-B7)/B7)*100 -> 6.035003
A8: 2023 | B8: =SUMIFS('Data Clean'!AD:AD,'Data Clean'!A:A,"Rural+Urban",'Data Clean'!B:B,A8,'Data Clean'!C:C,"January") -> 176.5 | C8: =SUMIFS('Data Clean'!AD:AD,'Data Clean'!A:A,"Rural+Urban",'Data Clean'!B:B,A8,'Data Clean'!C:C,"May") -> 179.1 | D8: =((C8-B8)/B8)*100 -> 1.4730878
A15: Comparison Table
A16: Category | B16: Jan 2019 Value | C16: Dec 2019 Value | D16: Growth %
A17: Vegetables | B17: 131.3 | C17: 217 | D17: =((C17 - B17) / B17) * 100 -> 65.270373
A18: Pulses and products | B18: 120.3 | C18: 138.3 | D18: =((C18 - B18) / B18) * 100 -> 14.962594
A19: Food and beverages | B19: 137.4 | C19: 155 | D19: =((C19 - B19) / B19) * 100 -> 12.809316
A20: Meat and fish | B20: 151.4 | C20: 165 | D20: =((C20 - B20) / B20) * 100 -> 8.9828269
A21: Egg | B21: 140.2 | C21: 151.1 | D21: =((C21 - B21) / B21) * 100 -> 7.7746077
A22: Fruits | B22: 135.4 | C22: 145.7 | D22: =((C22 - B22) / B22) * 100 -> 7.6070901
A23: Spices | B23: 139.4 | C23: 148.7 | D23: =((C23 - B23) / B23) * 100 -> 6.6714491
A24: Personal care and effects | B24: 132.8 | C24: 140.4 | D24: =((C24 - B24) / B24) * 100 -> 5.7228916
A25: Transport and communication | B25: 123.3 | C25: 129.8 | D25: =((C25 - B25) / B25) * 100 -> 5.2716951
A26: Cereals and products | B26: 137.1 | C26: 143.5 | D26: =((C26 - B26) / B26) * 100 -> 4.6681255
A27: Sugar and Confectionery | B27: 109.1 | C27: 114 | D27: =((C27 - B27) / B27) * 100 -> 4.4912924
A28: Milk and products | B28: 142.1 | C28: 148.3 | D28: =((C28 - B28) / B28) * 100 -> 4.3631246
... A42: Household goods and services | B42: 143.6 | C42: 145.8 | D42: =((C42 - B42) / B42) * 100 -> 1.5320334

Sheet Problem 3
A1: Year/Month | B1: Food Bucket Value | C1: Month On Month % Change | E1: Category | F1: May 22 Value | G1: May 23 Value | H1: Change (Absolute)
A2: 44682 | B2: =SUM('Data Clean'!D337:O337) -> 2065.6 | E2: Spices | F2: 184.9 | G2: 218 | H2: =G2-F2 -> 33.1
A3: 44713 | B3: =SUM('Data Clean'!D340:O340) -> 2087 | C3: =(B3-B2)/B2*100 -> 1.0360186 | E3: Cereals and products | F3: 154.1 | G3: 173.7 | H3: =G3-F3 -> 19.6
A4: 44743 | B4: =SUM('Data Clean'!D343:O343) -> 2091.3 | C4: =(B4-B3)/B3*100 -> 0.20603737 | E4: Milk and products | F4: 164.9 | G4: 179.5 | H4: =G4-F4 -> 14.6
A5: 44774 | B5: =SUM('Data Clean'!D346:O346) -> 2092.9 | C5: =(B5-B4)/B4*100 -> 0.076507436 | E5: Prepared meals, snacks, sweets etc. | F5: 182.5 | G5: 194.2 | H5: =G5-F5 -> 11.7
A6: 44805 | B6: =SUM('Data Clean'!D349:O349) -> 2103.1 | C6: =(B6-B5)/B5*100 -> 0.48736203 | E6: Pulses and products | F6: 164.7 | G6: 175.6 | H6: =G6-F6 -> 10.9
A7: 44835 | B7: =SUM('Data Clean'!D352:O352) -> 2117.7 | C7: =(B7-B6)/B6*100 -> 0.6942133 | E7: Egg | F7: 162.4 | G7: 173.2 | H7: =G7-F7 -> 10.8
A8: 44866 | B8: =SUM('Data Clean'!D355:O355) -> 2118.5 | C8: =(B8-B7)/B7*100 -> 0.037776833 | E8: Non-alcoholic beverages | F8: 167.1 | G8: 173.4 | H8: =G8-F8 -> 6.3
A9: 44896 | B9: =SUM('Data Clean'!D358:O358) -> 2107.5 | C9: =(B9-B8)/B8*100 -> -0.51923531 | E9: Sugar and Confectionery | F9: 119.7 | G9: 122.7 | H9: =G9-F9 -> 3
A10: 44927 | B10: =SUM('Data Clean'!D361:O361) -> 2116 | C10: =(B10-B9)/B9*100 -> 0.40332147 | E10: Fruits | F10: 171 | G10: 172.2 | H10: =G10-F10 -> 1.2
A11: 44958 | B11: =SUM('Data Clean'!D364:O364) -> 2102.1 | C11: =(B11-B10)/B10*100 -> -0.65689981 | E11: Meat and fish | F11: 217 | G11: 214.3 | H11: =G11-F11 -> -2.7
A12: 44986 | B12: =SUM('Data Clean'!D367:O367) -> 2102.2 | C12: =(B12-B11)/B11*100 -> 0.0047571476 | E12: Vegetables | F12: 174.9 | G12: 161 | H12: =G12-F12 -> -13.9
A13: 45017 | B13: =SUM('Data Clean'!D370:O370) -> 2111.7 | C13: =(B13-B12)/B12*100 -> 0.45190753 | E13: Oils and fats | F13: 202.4 | G13: 170 | H13: =G13-F13 -> -32.4
A14: 45047 | B14: =SUM('Data Clean'!D373:O373) -> 2127.8 | C14: =(B14-B13)/B13*100 -> 0.7624189

Sheet Problem 4
A1: Year | B1: Month | C1: General Index | D1: Health Index | E1: Transport Index | F1: Food Index | G1: General MoM % | H1: Health MoM % | I1: Transport MoM % | J1: Food MoM %
A2: 2019 | B2: December | C2: =SUMIFS('Data Clean'!$AD:$AD, 'Data Clean'!$A:$A, "Rural+Urban", 'Data Clean'!$B:$B, $A2, 'Data Clean'!$C:$C, $B2) -> 150.4 | D2: =SUMIFS('Data Clean'!$X:$X, 'Data Clean'!$A:$A, "Rural+Urban", 'Data Clean'!$B:$B, $A2, 'Data Clean'!$C:$C, $B2) -> 150.4 | E2: =SUMIFS('Data Clean'!$Y:$Y, 'Data Clean'!$A:$A, "Rural+Urban", 'Data Clean'!$B:$B, $A2, 'Data Clean'!$C:$C, $B2) -> 129.8 | F2: =SUMIFS('Data Clean'!$P:$P, 'Data Clean'!$A:$A, "Rural+Urban", 'Data Clean'!$B:$B, $A2, 'Data Clean'!$C:$C, $B2) -> 155
A3: 2020 | B3: January | C3: =SUMIFS('Data Clean'!$AD:$AD, 'Data Clean'!$A:$A, "Rural+Urban", 'Data Clean'!$B:$B, $A3, 'Data Clean'!$C:$C, $B3) -> 150.2 | D3: =SUMIFS('Data Clean'!$X:$X, 'Data Clean'!$A:$A, "Rural+Urban", 'Data Clean'!$B:$B, $A3, 'Data Clean'!$C:$C, $B3) -> 151.2 | E3: =SUMIFS('Data Clean'!$Y:$Y, 'Data Clean'!$A:$A, "Rural+Urban", 'Data Clean'!$B:$B, $A3, 'Data Clean'!$C:$C, $B3) -> 130.9 | F3: =SUMIFS('Data Clean'!$P:$P, 'Data Clean'!$A:$A, "Rural+Urban", 'Data Clean'!$B:$B, $A3, 'Data Clean'!$C:$C, $B3) -> 153.5 | G3: =((C3 - C2) / C2) * 100 -> -0.13297872 | H3: =((D3 - D2) / D2) * 100 -> 0.53191489 | I3: =((E3 - E2) / E2) * 100 -> 0.84745763 | J3: =((F3 - F2) / F2) * 100 -> -0.96774194 | L3: Pre-COVID Average (Dec '19 – Feb '20):
A4: 2020 | B4: February | C4: =SUMIFS('Data Clean'!$AD:$AD, 'Data Clean'!$A:$A, "Rural+Urban", 'Data Clean'!$B:$B, $A4, 'Data Clean'!$C:$C, $B4) -> 149.1 | D4: =SUMIFS('Data Clean'!$X:$X, 'Data Clean'!$A:$A, "Rural+Urban", 'Data Clean'!$B:$B, $A4, 'Data Clean'!$C:$C, $B4) -> 151.7 | E4: =SUMIFS('Data Clean'!$Y:$Y, 'Data Clean'!$A:$A, "Rural+Urban", 'Data Clean'!$B:$B, $A4, 'Data Clean'!$C:$C, $B4) -> 130.3 | F4: =SUMIFS('Data Clean'!$P:$P, 'Data Clean'!$A:$A, "Rural+Urban", 'Data Clean'!$B:$B, $A4, 'Data Clean'!$C:$C, $B4) -> 150.5 | G4: =((C4 - C3) / C3) * 100 -> -0.73235686 | H4: =((D4 - D3) / D3) * 100 -> 0.33068783 | I4: =((E4 - E3) / E3) * 100 -> -0.45836516 | J4: =((F4 - F3) / F3) * 100 -> -1.9543974 | L4: General | M4: Health | N4: Transport | O4: Food
A5: 2020 | B5: March | C5: =SUMIFS('Data Clean'!$AD:$AD, 'Data Clean'!$A:$A, "Rural+Urban", 'Data Clean'!$B:$B, $A5, 'Data Clean'!$C:$C, $B5) -> 148.6 | D5: =SUMIFS('Data Clean'!$X:$X, 'Data Clean'!$A:$A, "Rural+Urban", 'Data Clean'!$B:$B, $A5, 'Data Clean'!$C:$C, $B5) -> 152.3 | E5: =SUMIFS('Data Clean'!$Y:$Y, 'Data Clean'!$A:$A, "Rural+Urban", 'Data Clean'!$B:$B, $A5, 'Data Clean'!$C:$C, $B5) -> 129.9 | F5: =SUMIFS('Data Clean'!$P:$P, 'Data Clean'!$A:$A, "Rural+Urban", 'Data Clean'!$B:$B, $A5, 'Data Clean'!$C:$C, $B5) -> 148.9 | G5: =((C5 - C4) / C4) * 100 -> -0.33534541 | H5: =((D5 - D4) / D4) * 100 -> 0.39551747 | I5: =((E5 - E4) / E4) * 100 -> -0.30698388 | J5: =((F5 - F4) / F4) * 100 -> -1.0631229 | L5: =AVERAGE(G2:G4) -> -0.43266779 | M5: =AVERAGE(H2:H4) -> 0.43130136 | N5: =AVERAGE(I2:I4) -> 0.19454623 | O5: =AVERAGE(J2:J4) -> -1.4610697
A6: 2020 | B6: April | C6: =SUMIFS('Data Clean'!$AD:$AD, 'Data Clean'!$A:$A, "Rural+Urban", 'Data Clean'!$B:$B, $A6, 'Data Clean'!$C:$C, $B6) -> 149.3 | D6: =SUMIFS('Data Clean'!$X:$X, 'Data Clean'!$A:$A, "Rural+Urban", 'Data Clean'!$B:$B, $A6, 'Data Clean'!$C:$C, $B6) -> 150.7 | E6: =SUMIFS('Data Clean'!$Y:$Y, 'Data Clean'!$A:$A, "Rural+Urban", 'Data Clean'!$B:$B, $A6, 'Data Clean'!$C:$C, $B6) -> 130.4 | F6: =SUMIFS('Data Clean'!$P:$P, 'Data Clean'!$A:$A, "Rural+Urban", 'Data Clean'!$B:$B, $A6, 'Data Clean'!$C:$C, $B6) -> 151.4 | G6: =((C6 - C5) / C5) * 100 -> 0.47106326 | H6: =((D6 - D5) / D5) * 100 -> -1.0505581 | I6: =((E6 - E5) / E5) * 100 -> 0.38491147 | J6: =((F6 - F5) / F5) * 100 -> 1.6789792
A7: 2020 | B7: May | C7: =SUMIFS('Data Clean'!$AD:$AD, 'Data Clean'!$A:$A, "Rural+Urban", 'Data Clean'!$B:$B, $A7, 'Data Clean'!$C:$C, $B7) -> 149 | D7: =SUMIFS('Data Clean'!$X:$X, 'Data Clean'!$A:$A, "Rural+Urban", 'Data Clean'!$B:$B, $A7, 'Data Clean'!$C:$C, $B7) -> 151.6 | E7: =SUMIFS('Data Clean'!$Y:$Y, 'Data Clean'!$A:$A, "Rural+Urban", 'Data Clean'!$B:$B, $A7, 'Data Clean'!$C:$C, $B7) -> 130.2 | F7: =SUMIFS('Data Clean'!$P:$P, 'Data Clean'!$A:$A, "Rural+Urban", 'Data Clean'!$B:$B, $A7, 'Data Clean'!$C:$C, $B7) -> 150.3 | G7: =((C7 - C6) / C6) * 100 -> -0.20093771 | H7: =((D7 - D6) / D6) * 100 -> 0.59721301 | I7: =((E7 - E6) / E6) * 100 -> -0.15337423 | J7: =((F7 - F6) / F6) * 100 -> -0.72655218
A8: 2020 | B8: June | C8: =SUMIFS('Data Clean'!$AD:$AD, 'Data Clean'!$A:$A, "Rural+Urban", 'Data Clean'!$B:$B, $A8, 'Data Clean'!$C:$C, $B8) -> 151.8 | D8: =SUMIFS('Data Clean'!$X:$X, 'Data Clean'!$A:$A, "Rural+Urban", 'Data Clean'!$B:$B, $A8, 'Data Clean'!$C:$C, $B8) -> 154.4 | E8: =SUMIFS('Data Clean'!$Y:$Y, 'Data Clean'!$A:$A, "Rural+Urban", 'Data Clean'!$B:$B, $A8, 'Data Clean'!$C:$C, $B8) -> 135 | F8: =SUMIFS('Data Clean'!$P:$P, 'Data Clean'!$A:$A, "Rural+Urban", 'Data Clean'!$B:$B, $A8, 'Data Clean'!$C:$C, $B8) -> 154 | G8: =((C8 - C7) / C7) * 100 -> 1.8791946 | H8: =((D8 - D7) / D7) * 100 -> 1.8469657 | I8: =((E8 - E7) / E7) * 100 -> 3.6866359 | J8: =((F8 - F7) / F7) * 100 -> 2.4617432
L9: Post-COVID Average (Apr '20 – Jun '20)
L10: General | M10: Health | N10: Transport | O10: Food
L11: =AVERAGE(G6:G8) -> 0.71644006 | M11: =AVERAGE(H6:H8) -> 0.4645402 | N11: =AVERAGE(I6:I8) -> 1.3060577 | O11: =AVERAGE(J6:J8) -> 1.1380567
L13: Impact on each category in %
L14: General | M14: Health | N14: Transport | O14: Food
L15: =L11-L5 -> 1.1491079 | M15: =M11-M5 -> 0.033238837 | N15: =N11-N5 -> 1.1115115 | O15: =O11-O5 -> 2.5991264

Sheet Problem 5
A1: Date | B1: Oils Inflation | C1: Oil Price Change% | D1: Food Inflation | E1: Food Infl. Change% | F1: Fuel Inflation | G1: Fuel Infl. Change% | H1: Transport Inflation | I1: Transport Infl. Change%
A2: 44197 | B2: 150.9 | D2: 161 | F2: 147.9 | H2: 141.9
A3: 44228 | B3: 158.7 | C3: =(B3-B2)/B2 -> 0.051689861 | D3: 156.9 | E3: =(D3-D2)/D2 -> -0.025465839 | F3: 152.4 | G3: =(F3-F2)/F2 -> 0.030425963 | H3: 145.1 | I3: =(H3-H2)/H2 -> 0.022551092 | J3: Category | K3: Correlation Result | L3: Interpretation
A4: 44256 | B4: 163.9 | C4: =(B4-B3)/B3 -> 0.032766226 | D4: 156.7 | E4: =(D4-D3)/D3 -> -0.0012746973 | F4: 155.5 | G4: =(F4-F3)/F3 -> 0.020341207 | H4: 146.2 | I4: =(H4-H3)/H3 -> 0.0075809786 | J4: Food | K4: =CORREL(C3:C30,E3:E30) -> 0.060016551 | L4: Negligible Impact
A5: 44287 | B5: 170.1 | C5: =(B5-B4)/B4 -> 0.037827944 | D5: 158 | E5: =(D5-D4)/D4 -> 0.0082961072 | F5: 155.6 | G5: =(F5-F4)/F4 -> 0.00064308682 | H5: 146.6 | I5: =(H5-H4)/H4 -> 0.0027359781 | J5: Fuel | K5: =CORREL(C3:C30,G3:G30) -> 0.55700401 | L5: Moderately Impacted
A6: 44317 | B6: 178.7 | C6: =(B6-B5)/B5 -> 0.050558495 | D6: 160.7 | E6: =(D6-D5)/D5 -> 0.017088608 | F6: 159.4 | G6: =(F6-F5)/F5 -> 0.024421594 | H6: 148.9 | I6: =(H6-H5)/H5 -> 0.01568895 | J6: Transport | K6: =CORREL(C3:C30,I3:I30) -> 0.48641035 | L6: Moderately Impacted but less than Fuel
A7: 44348 | B7: 183.7 | C7: =(B7-B6)/B6 -> 0.027979855 | D7: 162.6 | E7: =(D7-D6)/D6 -> 0.011823273 | F7: 159.8 | G7: =(F7-F6)/F6 -> 0.0025094103 | H7: 150.7 | I7: =(H7-H6)/H6 -> 0.01208865
A8: 44378 | B8: 182.1 | C8: =(B8-B7)/B7 -> -0.008709853 | D8: 164 | E8: =(D8-D7)/D7 -> 0.0086100861 | F8: 160.7 | G8: =(F8-F7)/F7 -> 0.0056320401 | H8: 153.1 | I8: =(H8-H7)/H7 -> 0.01592568
A9: 44409 | B9: 188 | C9: =(B9-B8)/B8 -> 0.03239978 | D9: 164 | E9: =(D9-D8)/D8 -> 0 | F9: 162.6 | G9: =(F9-F8)/F8 -> 0.011823273 | H9: 154 | I9: =(H9-H8)/H8 -> 0.0058785108
A10: 44440 | B10: 188 | C10: =(B10-B9)/B9 -> 0 | D10: 164 | E10: =(D10-D9)/D9 -> 0 | F10: 162.6 | G10: =(F10-F9)/F9 -> 0 | H10: 154 | I10: =(H10-H9)/H9 -> 0
A11: 44470 | B11: 190.6 | C11: =(B11-B10)/B10 -> 0.013829787 | D11: 167.7 | E11: =(D11-D10)/D10 -> 0.022560976 | F11: 164.2 | G11: =(F11-F10)/F10 -> 0.0098400984 | H11: 155.7 | I11: =(H11-H10)/H10 -> 0.011038961
A12: 44501 | B12: 190.1 | C12: =(B12-B11)/B11 -> -0.0026232949 | D12: 169.7 | E12: =(D12-D11)/D11 -> 0.011926058 | F12: 163.9 | G12: =(F12-F11)/F11 -> -0.0018270402 | H12: 154.8 | I12: =(H12-H11)/H11 -> -0.0057803468
A13: 44531 | B13: 187.6 | C13: =(B13-B12)/B12 -> -0.013150973 | D13: 168.2 | E13: =(D13-D12)/D12 -> -0.0088391279 | F13: 164.1 | G13: =(F13-F12)/F12 -> 0.0012202563 | H13: 155.7 | I13: =(H13-H12)/H12 -> 0.0058139535
A14: 44562 | B14: 184.7 | C14: =(B14-B13)/B13 -> -0.015458422 | D14: 166.4 | E14: =(D14-D13)/D13 -> -0.010701546 | F14: 164.2 | G14: =(F14-F13)/F13 -> 0.00060938452 | H14: 156.5 | I14: =(H14-H13)/H13 -> 0.0051380861
A15: 44593 | B15: 184.9 | C15: =(B15-B14)/B14 -> 0.001082837 | D15: 166.2 | E15: =(D15-D14)/D14 -> -0.0012019231 | F15: 165.7 | G15: =(F15-F14)/F14 -> 0.009135201 | H15: 156.9 | I15: =(H15-H14)/H14 -> 0.0025559105
A16: 44621 | B16: 194.6 | C16: =(B16-B15)/B15 -> 0.05246079 | D16: 168.4 | E16: =(D16-D15)/D15 -> 0.013237064 | F16: 167.2 | G16: =(F16-F15)/F15 -> 0.0090525045 | H16: 157.9 | I16: =(H16-H15)/H15 -> 0.0063734863
A17: 44652 | B17: 199.5 | C17: =(B17-B16)/B16 -> 0.025179856 | D17: 170.8 | E17: =(D17-D16)/D16 -> 0.014251781 | F17: 172.2 | G17: =(F17-F16)/F16 -> 0.029904306 | H17: 162.6 | I17: =(H17-H16)/H16 -> 0.029765674
A18: 44682 | B18: 202.4 | C18: =(B18-B17)/B17 -> 0.014536341 | D18: 173.3 | E18: =(D18-D17)/D17 -> 0.014637002 | F18: 174.6 | G18: =(F18-F17)/F17 -> 0.013937282 | H18: 163 | I18: =(H18-H17)/H17 -> 0.0024600246
... A30: 45047 | B30: 170 | C30: =(B30-B29)/B29 -> -0.028016009 | D30: 179.1 | E30: =(D30-D29)/D29 -> 0.0067453626 | F30: 182.8 | G30: =(F30-F29)/F29 -> 0.0060539351 | H30: 164.8 | I30: =(H30-H29)/H29 -> 0.0018237082

Sheet Summary
